[2025-03-21T20:06:01.876+0000] {taskinstance.py:1157} INFO - Dependencies all met for dep_context=non-requeueable deps ti=<TaskInstance: external_customer_pipeline.fetch_and_store_customer_data manual__2025-03-21T20:05:48.487457+00:00 [queued]>
[2025-03-21T20:06:01.895+0000] {taskinstance.py:1157} INFO - Dependencies all met for dep_context=requeueable deps ti=<TaskInstance: external_customer_pipeline.fetch_and_store_customer_data manual__2025-03-21T20:05:48.487457+00:00 [queued]>
[2025-03-21T20:06:01.896+0000] {taskinstance.py:1359} INFO - Starting attempt 1 of 2
[2025-03-21T20:06:01.924+0000] {taskinstance.py:1380} INFO - Executing <Task(PythonOperator): fetch_and_store_customer_data> on 2025-03-21 20:05:48.487457+00:00
[2025-03-21T20:06:01.930+0000] {standard_task_runner.py:57} INFO - Started process 624 to run task
[2025-03-21T20:06:01.946+0000] {standard_task_runner.py:84} INFO - Running: ['***', 'tasks', 'run', 'external_customer_pipeline', 'fetch_and_store_customer_data', 'manual__2025-03-21T20:05:48.487457+00:00', '--job-id', '865', '--raw', '--subdir', 'DAGS_FOLDER/pipeline_batch.py', '--cfg-path', '/tmp/tmpidj_ml8u']
[2025-03-21T20:06:01.953+0000] {standard_task_runner.py:85} INFO - Job 865: Subtask fetch_and_store_customer_data
[2025-03-21T20:06:02.047+0000] {task_command.py:415} INFO - Running <TaskInstance: external_customer_pipeline.fetch_and_store_customer_data manual__2025-03-21T20:05:48.487457+00:00 [running]> on host 4f421949e8a6
[2025-03-21T20:06:02.198+0000] {taskinstance.py:1660} INFO - Exporting env vars: AIRFLOW_CTX_DAG_OWNER='***' AIRFLOW_CTX_DAG_ID='external_customer_pipeline' AIRFLOW_CTX_TASK_ID='fetch_and_store_customer_data' AIRFLOW_CTX_EXECUTION_DATE='2025-03-21T20:05:48.487457+00:00' AIRFLOW_CTX_TRY_NUMBER='1' AIRFLOW_CTX_DAG_RUN_ID='manual__2025-03-21T20:05:48.487457+00:00'
[2025-03-21T20:06:02.217+0000] {logging_mixin.py:151} WARNING - /home/***/.local/lib/python3.8/site-packages/***/utils/context.py:314 AirflowContextDeprecationWarning: Accessing 'execution_date' from the template is deprecated and will be removed in a future version. Please use 'data_interval_start' or 'logical_date' instead.
[2025-03-21T20:06:10.216+0000] {pipeline_batch.py:44} INFO - Discord message sent successfully
[2025-03-21T20:06:10.222+0000] {taskinstance.py:1935} ERROR - Task failed with exception
Traceback (most recent call last):
  File "/home/airflow/.local/lib/python3.8/site-packages/airflow/operators/python.py", line 192, in execute
    return_value = self.execute_callable()
  File "/home/airflow/.local/lib/python3.8/site-packages/airflow/operators/python.py", line 209, in execute_callable
    return self.python_callable(*self.op_args, **self.op_kwargs)
  File "/opt/airflow/dags/pipeline_batch.py", line 167, in fetch_and_store_customer_data
    subprocess.run(
  File "/usr/local/lib/python3.8/subprocess.py", line 516, in run
    raise CalledProcessError(retcode, process.args,
subprocess.CalledProcessError: Command '['docker', 'exec', 'hive', 'hdfs', 'dfs', '-put', '-f', '/tmp/customer_20250321_200548.json', '/data/customer/customer_20250321_200548.json']' returned non-zero exit status 1.
[2025-03-21T20:06:10.244+0000] {taskinstance.py:1398} INFO - Marking task as UP_FOR_RETRY. dag_id=external_customer_pipeline, task_id=fetch_and_store_customer_data, execution_date=20250321T200548, start_date=20250321T200601, end_date=20250321T200610
[2025-03-21T20:06:10.295+0000] {standard_task_runner.py:104} ERROR - Failed to execute job 865 for task fetch_and_store_customer_data (Command '['docker', 'exec', 'hive', 'hdfs', 'dfs', '-put', '-f', '/tmp/customer_20250321_200548.json', '/data/customer/customer_20250321_200548.json']' returned non-zero exit status 1.; 624)
[2025-03-21T20:06:10.318+0000] {local_task_job_runner.py:228} INFO - Task exited with return code 1
[2025-03-21T20:06:10.347+0000] {taskinstance.py:2776} INFO - 0 downstream tasks scheduled from follow-on schedule check
