[2025-03-21T13:34:31.964+0000] {taskinstance.py:1157} INFO - Dependencies all met for dep_context=non-requeueable deps ti=<TaskInstance: transactions_pipeline.detect_fraud_batch_20250321_131741 manual__2025-03-21T13:31:53.143260+00:00 [queued]>
[2025-03-21T13:34:32.000+0000] {taskinstance.py:1157} INFO - Dependencies all met for dep_context=requeueable deps ti=<TaskInstance: transactions_pipeline.detect_fraud_batch_20250321_131741 manual__2025-03-21T13:31:53.143260+00:00 [queued]>
[2025-03-21T13:34:32.001+0000] {taskinstance.py:1359} INFO - Starting attempt 1 of 1
[2025-03-21T13:34:32.049+0000] {taskinstance.py:1380} INFO - Executing <Task(BashOperator): detect_fraud_batch_20250321_131741> on 2025-03-21 13:31:53.143260+00:00
[2025-03-21T13:34:32.065+0000] {standard_task_runner.py:57} INFO - Started process 2851 to run task
[2025-03-21T13:34:32.072+0000] {standard_task_runner.py:84} INFO - Running: ['***', 'tasks', 'run', 'transactions_pipeline', 'detect_fraud_batch_20250321_131741', 'manual__2025-03-21T13:31:53.143260+00:00', '--job-id', '658', '--raw', '--subdir', 'DAGS_FOLDER/fraud_detection_pipeline.py', '--cfg-path', '/tmp/tmp3sh32zm9']
[2025-03-21T13:34:32.077+0000] {standard_task_runner.py:85} INFO - Job 658: Subtask detect_fraud_batch_20250321_131741
[2025-03-21T13:34:32.236+0000] {task_command.py:415} INFO - Running <TaskInstance: transactions_pipeline.detect_fraud_batch_20250321_131741 manual__2025-03-21T13:31:53.143260+00:00 [running]> on host 1b7c3466167a
[2025-03-21T13:34:32.483+0000] {taskinstance.py:1660} INFO - Exporting env vars: AIRFLOW_CTX_DAG_EMAIL='rabiizahnoune7@gmail.com' AIRFLOW_CTX_DAG_OWNER='***' AIRFLOW_CTX_DAG_ID='transactions_pipeline' AIRFLOW_CTX_TASK_ID='detect_fraud_batch_20250321_131741' AIRFLOW_CTX_EXECUTION_DATE='2025-03-21T13:31:53.143260+00:00' AIRFLOW_CTX_TRY_NUMBER='1' AIRFLOW_CTX_DAG_RUN_ID='manual__2025-03-21T13:31:53.143260+00:00'
[2025-03-21T13:34:32.496+0000] {subprocess.py:63} INFO - Tmp dir root location: /tmp
[2025-03-21T13:34:32.498+0000] {subprocess.py:75} INFO - Running command: ['/bin/bash', '-c', '\n            docker exec hive spark-submit --master spark://localhost:7077 /hive/scripts/detect_fraud.py "batch_20250321_131741"\n            ']
[2025-03-21T13:34:32.528+0000] {subprocess.py:86} INFO - Output:
[2025-03-21T13:35:04.440+0000] {subprocess.py:93} INFO - 25/03/21 13:35:04 INFO SparkContext: Running Spark version 3.5.0
[2025-03-21T13:35:04.454+0000] {subprocess.py:93} INFO - 25/03/21 13:35:04 INFO SparkContext: OS info Linux, 5.15.167.4-microsoft-standard-WSL2, amd64
[2025-03-21T13:35:04.455+0000] {subprocess.py:93} INFO - 25/03/21 13:35:04 INFO SparkContext: Java version 1.8.0_342
[2025-03-21T13:35:05.656+0000] {subprocess.py:93} INFO - 25/03/21 13:35:05 WARN NativeCodeLoader: Unable to load native-hadoop library for your platform... using builtin-java classes where applicable
[2025-03-21T13:35:07.038+0000] {subprocess.py:93} INFO - 25/03/21 13:35:07 INFO ResourceUtils: ==============================================================
[2025-03-21T13:35:07.050+0000] {subprocess.py:93} INFO - 25/03/21 13:35:07 INFO ResourceUtils: No custom resources configured for spark.driver.
[2025-03-21T13:35:07.051+0000] {subprocess.py:93} INFO - 25/03/21 13:35:07 INFO ResourceUtils: ==============================================================
[2025-03-21T13:35:07.052+0000] {subprocess.py:93} INFO - 25/03/21 13:35:07 INFO SparkContext: Submitted application: FraudDetection
[2025-03-21T13:35:07.937+0000] {subprocess.py:93} INFO - 25/03/21 13:35:07 INFO ResourceProfile: Default ResourceProfile created, executor resources: Map(memory -> name: memory, amount: 1024, script: , vendor: , offHeap -> name: offHeap, amount: 0, script: , vendor: ), task resources: Map(cpus -> name: cpus, amount: 1.0)
[2025-03-21T13:35:08.546+0000] {subprocess.py:93} INFO - 25/03/21 13:35:08 INFO ResourceProfile: Limiting resource is cpu
[2025-03-21T13:35:08.637+0000] {subprocess.py:93} INFO - 25/03/21 13:35:08 INFO ResourceProfileManager: Added ResourceProfile id: 0
[2025-03-21T13:35:09.739+0000] {subprocess.py:93} INFO - 25/03/21 13:35:09 INFO SecurityManager: Changing view acls to: root
[2025-03-21T13:35:09.742+0000] {subprocess.py:93} INFO - 25/03/21 13:35:09 INFO SecurityManager: Changing modify acls to: root
[2025-03-21T13:35:09.744+0000] {subprocess.py:93} INFO - 25/03/21 13:35:09 INFO SecurityManager: Changing view acls groups to:
[2025-03-21T13:35:09.753+0000] {subprocess.py:93} INFO - 25/03/21 13:35:09 INFO SecurityManager: Changing modify acls groups to:
[2025-03-21T13:35:09.754+0000] {subprocess.py:93} INFO - 25/03/21 13:35:09 INFO SecurityManager: SecurityManager: authentication disabled; ui acls disabled; users with view permissions: root; groups with view permissions: EMPTY; users with modify permissions: root; groups with modify permissions: EMPTY
[2025-03-21T13:35:14.203+0000] {subprocess.py:93} INFO - 25/03/21 13:35:14 INFO Utils: Successfully started service 'sparkDriver' on port 45907.
[2025-03-21T13:35:14.916+0000] {subprocess.py:93} INFO - 25/03/21 13:35:14 INFO SparkEnv: Registering MapOutputTracker
[2025-03-21T13:35:15.407+0000] {subprocess.py:93} INFO - 25/03/21 13:35:15 INFO SparkEnv: Registering BlockManagerMaster
[2025-03-21T13:35:15.721+0000] {subprocess.py:93} INFO - 25/03/21 13:35:15 INFO BlockManagerMasterEndpoint: Using org.apache.spark.storage.DefaultTopologyMapper for getting topology information
[2025-03-21T13:35:15.799+0000] {subprocess.py:93} INFO - 25/03/21 13:35:15 INFO BlockManagerMasterEndpoint: BlockManagerMasterEndpoint up
[2025-03-21T13:35:15.802+0000] {subprocess.py:93} INFO - 25/03/21 13:35:15 INFO SparkEnv: Registering BlockManagerMasterHeartbeat
[2025-03-21T13:35:17.317+0000] {subprocess.py:93} INFO - 25/03/21 13:35:17 INFO DiskBlockManager: Created local directory at /tmp/blockmgr-417152d6-5b24-4fe7-b243-5187e9bd323b
[2025-03-21T13:35:17.605+0000] {subprocess.py:93} INFO - 25/03/21 13:35:17 INFO MemoryStore: MemoryStore started with capacity 366.3 MiB
[2025-03-21T13:35:18.006+0000] {subprocess.py:93} INFO - 25/03/21 13:35:17 INFO SparkEnv: Registering OutputCommitCoordinator
[2025-03-21T13:35:22.210+0000] {subprocess.py:93} INFO - 25/03/21 13:35:22 INFO JettyUtils: Start Jetty 0.0.0.0:4040 for SparkUI
[2025-03-21T13:35:24.506+0000] {subprocess.py:93} INFO - 25/03/21 13:35:24 WARN Utils: Service 'SparkUI' could not bind on port 4040. Attempting port 4041.
[2025-03-21T13:35:24.509+0000] {subprocess.py:93} INFO - 25/03/21 13:35:24 WARN Utils: Service 'SparkUI' could not bind on port 4041. Attempting port 4042.
[2025-03-21T13:35:24.621+0000] {subprocess.py:93} INFO - 25/03/21 13:35:24 WARN Utils: Service 'SparkUI' could not bind on port 4042. Attempting port 4043.
[2025-03-21T13:35:24.624+0000] {subprocess.py:93} INFO - 25/03/21 13:35:24 WARN Utils: Service 'SparkUI' could not bind on port 4043. Attempting port 4044.
[2025-03-21T13:35:24.624+0000] {subprocess.py:93} INFO - 25/03/21 13:35:24 WARN Utils: Service 'SparkUI' could not bind on port 4044. Attempting port 4045.
[2025-03-21T13:35:24.713+0000] {subprocess.py:93} INFO - 25/03/21 13:35:24 INFO Utils: Successfully started service 'SparkUI' on port 4045.
[2025-03-21T13:35:29.210+0000] {subprocess.py:93} INFO - 25/03/21 13:35:29 INFO StandaloneAppClient$ClientEndpoint: Connecting to master spark://localhost:7077...
[2025-03-21T13:35:30.910+0000] {subprocess.py:93} INFO - 25/03/21 13:35:30 INFO TransportClientFactory: Successfully created connection to localhost/127.0.0.1:7077 after 989 ms (0 ms spent in bootstraps)
[2025-03-21T13:35:33.511+0000] {subprocess.py:93} INFO - 25/03/21 13:35:33 INFO StandaloneSchedulerBackend: Connected to Spark cluster with app ID app-20250321133533-0014
[2025-03-21T13:35:33.797+0000] {subprocess.py:93} INFO - 25/03/21 13:35:33 INFO Utils: Successfully started service 'org.apache.spark.network.netty.NettyBlockTransferService' on port 46867.
[2025-03-21T13:35:33.806+0000] {subprocess.py:93} INFO - 25/03/21 13:35:33 INFO NettyBlockTransferService: Server created on e3006a54eed1:46867
[2025-03-21T13:35:33.808+0000] {subprocess.py:93} INFO - 25/03/21 13:35:33 INFO BlockManager: Using org.apache.spark.storage.RandomBlockReplicationPolicy for block replication policy
[2025-03-21T13:35:33.914+0000] {subprocess.py:93} INFO - 25/03/21 13:35:33 INFO BlockManagerMaster: Registering BlockManager BlockManagerId(driver, e3006a54eed1, 46867, None)
[2025-03-21T13:35:34.004+0000] {subprocess.py:93} INFO - 25/03/21 13:35:34 INFO BlockManagerMasterEndpoint: Registering block manager e3006a54eed1:46867 with 366.3 MiB RAM, BlockManagerId(driver, e3006a54eed1, 46867, None)
[2025-03-21T13:35:34.102+0000] {subprocess.py:93} INFO - 25/03/21 13:35:34 INFO BlockManagerMaster: Registered BlockManager BlockManagerId(driver, e3006a54eed1, 46867, None)
[2025-03-21T13:35:34.104+0000] {subprocess.py:93} INFO - 25/03/21 13:35:34 INFO BlockManager: Initialized BlockManager: BlockManagerId(driver, e3006a54eed1, 46867, None)
[2025-03-21T13:35:40.883+0000] {subprocess.py:93} INFO - 25/03/21 13:35:40 INFO StandaloneSchedulerBackend: SchedulerBackend is ready for scheduling beginning after reached minRegisteredResourcesRatio: 0.0
[2025-03-21T13:35:48.479+0000] {subprocess.py:93} INFO - Spark version: 3.5.0
[2025-03-21T13:35:50.382+0000] {subprocess.py:93} INFO - 25/03/21 13:35:50 INFO SharedState: Setting hive.metastore.warehouse.dir ('null') to the value of spark.sql.warehouse.dir.
[2025-03-21T13:35:59.976+0000] {subprocess.py:93} INFO - 25/03/21 13:35:59 INFO SharedState: Warehouse path is 'hdfs://localhost:9000/data/warehouse'.
[2025-03-21T13:36:21.513+0000] {subprocess.py:93} INFO - 25/03/21 13:36:21 INFO InMemoryFileIndex: It took 1199 ms to list leaf files for 1 paths.
[2025-03-21T13:36:31.224+0000] {subprocess.py:93} INFO - 25/03/21 13:36:31 INFO SparkContext: Starting job: parquet at NativeMethodAccessorImpl.java:0
[2025-03-21T13:36:32.350+0000] {subprocess.py:93} INFO - 25/03/21 13:36:32 INFO DAGScheduler: Got job 0 (parquet at NativeMethodAccessorImpl.java:0) with 1 output partitions
[2025-03-21T13:36:32.352+0000] {subprocess.py:93} INFO - 25/03/21 13:36:32 INFO DAGScheduler: Final stage: ResultStage 0 (parquet at NativeMethodAccessorImpl.java:0)
[2025-03-21T13:36:32.352+0000] {subprocess.py:93} INFO - 25/03/21 13:36:32 INFO DAGScheduler: Parents of final stage: List()
[2025-03-21T13:36:32.631+0000] {subprocess.py:93} INFO - 25/03/21 13:36:32 INFO DAGScheduler: Missing parents: List()
[2025-03-21T13:36:33.460+0000] {subprocess.py:93} INFO - 25/03/21 13:36:33 INFO DAGScheduler: Submitting ResultStage 0 (MapPartitionsRDD[1] at parquet at NativeMethodAccessorImpl.java:0), which has no missing parents
[2025-03-21T13:36:35.785+0000] {subprocess.py:93} INFO - 25/03/21 13:36:35 INFO AsyncEventQueue: Process of event SparkListenerJobStart(0,1742564192603,WrappedArray(org.apache.spark.scheduler.StageInfo@338fd781),{spark.rdd.scope.noOverride=true, spark.rdd.scope={"id":"2","name":"collect"}}) by listener AppStatusListener took 3.822561449s.
[2025-03-21T13:36:35.894+0000] {subprocess.py:93} INFO - 25/03/21 13:36:35 INFO MemoryStore: Block broadcast_0 stored as values in memory (estimated size 103.3 KiB, free 366.2 MiB)
[2025-03-21T13:36:37.604+0000] {subprocess.py:93} INFO - 25/03/21 13:36:37 INFO MemoryStore: Block broadcast_0_piece0 stored as bytes in memory (estimated size 37.2 KiB, free 366.2 MiB)
[2025-03-21T13:36:37.786+0000] {subprocess.py:93} INFO - 25/03/21 13:36:37 INFO BlockManagerInfo: Added broadcast_0_piece0 in memory on e3006a54eed1:46867 (size: 37.2 KiB, free: 366.3 MiB)
[2025-03-21T13:36:37.990+0000] {subprocess.py:93} INFO - 25/03/21 13:36:37 INFO SparkContext: Created broadcast 0 from broadcast at DAGScheduler.scala:1580
[2025-03-21T13:36:38.608+0000] {subprocess.py:93} INFO - 25/03/21 13:36:38 INFO DAGScheduler: Submitting 1 missing tasks from ResultStage 0 (MapPartitionsRDD[1] at parquet at NativeMethodAccessorImpl.java:0) (first 15 tasks are for partitions Vector(0))
[2025-03-21T13:36:38.612+0000] {subprocess.py:93} INFO - 25/03/21 13:36:38 INFO TaskSchedulerImpl: Adding task set 0.0 with 1 tasks resource profile 0
[2025-03-21T13:36:53.791+0000] {subprocess.py:93} INFO - 25/03/21 13:36:53 WARN TaskSchedulerImpl: Initial job has not accepted any resources; check your cluster UI to ensure that workers are registered and have sufficient resources
[2025-03-21T13:37:08.785+0000] {subprocess.py:93} INFO - 25/03/21 13:37:08 WARN TaskSchedulerImpl: Initial job has not accepted any resources; check your cluster UI to ensure that workers are registered and have sufficient resources
[2025-03-21T13:37:23.784+0000] {subprocess.py:93} INFO - 25/03/21 13:37:23 WARN TaskSchedulerImpl: Initial job has not accepted any resources; check your cluster UI to ensure that workers are registered and have sufficient resources
[2025-03-21T13:37:38.782+0000] {subprocess.py:93} INFO - 25/03/21 13:37:38 WARN TaskSchedulerImpl: Initial job has not accepted any resources; check your cluster UI to ensure that workers are registered and have sufficient resources
[2025-03-21T13:37:55.731+0000] {subprocess.py:93} INFO - 25/03/21 13:37:55 WARN TaskSchedulerImpl: Initial job has not accepted any resources; check your cluster UI to ensure that workers are registered and have sufficient resources
[2025-03-21T13:38:09.217+0000] {subprocess.py:93} INFO - 25/03/21 13:38:08 WARN TaskSchedulerImpl: Initial job has not accepted any resources; check your cluster UI to ensure that workers are registered and have sufficient resources
[2025-03-21T13:38:14.821+0000] {job.py:219} ERROR - Job heartbeat got an exception
Traceback (most recent call last):
  File "/home/airflow/.local/lib/python3.8/site-packages/sqlalchemy/engine/base.py", line 3371, in _wrap_pool_connect
    return fn()
  File "/home/airflow/.local/lib/python3.8/site-packages/sqlalchemy/pool/base.py", line 327, in connect
    return _ConnectionFairy._checkout(self)
  File "/home/airflow/.local/lib/python3.8/site-packages/sqlalchemy/pool/base.py", line 894, in _checkout
    fairy = _ConnectionRecord.checkout(pool)
  File "/home/airflow/.local/lib/python3.8/site-packages/sqlalchemy/pool/base.py", line 493, in checkout
    rec = pool._do_get()
  File "/home/airflow/.local/lib/python3.8/site-packages/sqlalchemy/pool/impl.py", line 256, in _do_get
    return self._create_connection()
  File "/home/airflow/.local/lib/python3.8/site-packages/sqlalchemy/pool/base.py", line 273, in _create_connection
    return _ConnectionRecord(self)
  File "/home/airflow/.local/lib/python3.8/site-packages/sqlalchemy/pool/base.py", line 388, in __init__
    self.__connect()
  File "/home/airflow/.local/lib/python3.8/site-packages/sqlalchemy/pool/base.py", line 691, in __connect
    pool.logger.debug("Error on connect(): %s", e)
  File "/home/airflow/.local/lib/python3.8/site-packages/sqlalchemy/util/langhelpers.py", line 70, in __exit__
    compat.raise_(
  File "/home/airflow/.local/lib/python3.8/site-packages/sqlalchemy/util/compat.py", line 211, in raise_
    raise exception
  File "/home/airflow/.local/lib/python3.8/site-packages/sqlalchemy/pool/base.py", line 686, in __connect
    self.dbapi_connection = connection = pool._invoke_creator(self)
  File "/home/airflow/.local/lib/python3.8/site-packages/sqlalchemy/engine/create.py", line 574, in connect
    return dialect.connect(*cargs, **cparams)
  File "/home/airflow/.local/lib/python3.8/site-packages/sqlalchemy/engine/default.py", line 598, in connect
    return self.dbapi.connect(*cargs, **cparams)
  File "/home/airflow/.local/lib/python3.8/site-packages/psycopg2/__init__.py", line 122, in connect
    conn = _connect(dsn, connection_factory=connection_factory, **kwasync)
psycopg2.OperationalError: could not translate host name "postgres" to address: Temporary failure in name resolution


The above exception was the direct cause of the following exception:

Traceback (most recent call last):
  File "/home/airflow/.local/lib/python3.8/site-packages/airflow/jobs/job.py", line 190, in heartbeat
    session.merge(self)
  File "/home/airflow/.local/lib/python3.8/site-packages/sqlalchemy/orm/session.py", line 3056, in merge
    return self._merge(
  File "/home/airflow/.local/lib/python3.8/site-packages/sqlalchemy/orm/session.py", line 3136, in _merge
    merged = self.get(
  File "/home/airflow/.local/lib/python3.8/site-packages/sqlalchemy/orm/session.py", line 2853, in get
    return self._get_impl(
  File "/home/airflow/.local/lib/python3.8/site-packages/sqlalchemy/orm/session.py", line 2975, in _get_impl
    return db_load_fn(
  File "/home/airflow/.local/lib/python3.8/site-packages/sqlalchemy/orm/loading.py", line 530, in load_on_pk_identity
    session.execute(
  File "/home/airflow/.local/lib/python3.8/site-packages/sqlalchemy/orm/session.py", line 1716, in execute
    conn = self._connection_for_bind(bind)
  File "/home/airflow/.local/lib/python3.8/site-packages/sqlalchemy/orm/session.py", line 1555, in _connection_for_bind
    return self._transaction._connection_for_bind(
  File "/home/airflow/.local/lib/python3.8/site-packages/sqlalchemy/orm/session.py", line 750, in _connection_for_bind
    conn = bind.connect()
  File "/home/airflow/.local/lib/python3.8/site-packages/sqlalchemy/future/engine.py", line 406, in connect
    return super(Engine, self).connect()
  File "/home/airflow/.local/lib/python3.8/site-packages/sqlalchemy/engine/base.py", line 3325, in connect
    return self._connection_cls(self, close_with_result=close_with_result)
  File "/home/airflow/.local/lib/python3.8/site-packages/sqlalchemy/engine/base.py", line 96, in __init__
    else engine.raw_connection()
  File "/home/airflow/.local/lib/python3.8/site-packages/sqlalchemy/engine/base.py", line 3404, in raw_connection
    return self._wrap_pool_connect(self.pool.connect, _connection)
  File "/home/airflow/.local/lib/python3.8/site-packages/sqlalchemy/engine/base.py", line 3374, in _wrap_pool_connect
    Connection._handle_dbapi_exception_noconnection(
  File "/home/airflow/.local/lib/python3.8/site-packages/sqlalchemy/engine/base.py", line 2208, in _handle_dbapi_exception_noconnection
    util.raise_(
  File "/home/airflow/.local/lib/python3.8/site-packages/sqlalchemy/util/compat.py", line 211, in raise_
    raise exception
  File "/home/airflow/.local/lib/python3.8/site-packages/sqlalchemy/engine/base.py", line 3371, in _wrap_pool_connect
    return fn()
  File "/home/airflow/.local/lib/python3.8/site-packages/sqlalchemy/pool/base.py", line 327, in connect
    return _ConnectionFairy._checkout(self)
  File "/home/airflow/.local/lib/python3.8/site-packages/sqlalchemy/pool/base.py", line 894, in _checkout
    fairy = _ConnectionRecord.checkout(pool)
  File "/home/airflow/.local/lib/python3.8/site-packages/sqlalchemy/pool/base.py", line 493, in checkout
    rec = pool._do_get()
  File "/home/airflow/.local/lib/python3.8/site-packages/sqlalchemy/pool/impl.py", line 256, in _do_get
    return self._create_connection()
  File "/home/airflow/.local/lib/python3.8/site-packages/sqlalchemy/pool/base.py", line 273, in _create_connection
    return _ConnectionRecord(self)
  File "/home/airflow/.local/lib/python3.8/site-packages/sqlalchemy/pool/base.py", line 388, in __init__
    self.__connect()
  File "/home/airflow/.local/lib/python3.8/site-packages/sqlalchemy/pool/base.py", line 691, in __connect
    pool.logger.debug("Error on connect(): %s", e)
  File "/home/airflow/.local/lib/python3.8/site-packages/sqlalchemy/util/langhelpers.py", line 70, in __exit__
    compat.raise_(
  File "/home/airflow/.local/lib/python3.8/site-packages/sqlalchemy/util/compat.py", line 211, in raise_
    raise exception
  File "/home/airflow/.local/lib/python3.8/site-packages/sqlalchemy/pool/base.py", line 686, in __connect
    self.dbapi_connection = connection = pool._invoke_creator(self)
  File "/home/airflow/.local/lib/python3.8/site-packages/sqlalchemy/engine/create.py", line 574, in connect
    return dialect.connect(*cargs, **cparams)
  File "/home/airflow/.local/lib/python3.8/site-packages/sqlalchemy/engine/default.py", line 598, in connect
    return self.dbapi.connect(*cargs, **cparams)
  File "/home/airflow/.local/lib/python3.8/site-packages/psycopg2/__init__.py", line 122, in connect
    conn = _connect(dsn, connection_factory=connection_factory, **kwasync)
sqlalchemy.exc.OperationalError: (psycopg2.OperationalError) could not translate host name "postgres" to address: Temporary failure in name resolution

(Background on this error at: https://sqlalche.me/e/14/e3q8)
[2025-03-21T13:38:23.833+0000] {subprocess.py:93} INFO - 25/03/21 13:38:23 WARN TaskSchedulerImpl: Initial job has not accepted any resources; check your cluster UI to ensure that workers are registered and have sufficient resources
[2025-03-21T13:38:38.868+0000] {subprocess.py:93} INFO - 25/03/21 13:38:38 WARN TaskSchedulerImpl: Initial job has not accepted any resources; check your cluster UI to ensure that workers are registered and have sufficient resources
[2025-03-21T13:38:53.833+0000] {subprocess.py:93} INFO - 25/03/21 13:38:53 WARN TaskSchedulerImpl: Initial job has not accepted any resources; check your cluster UI to ensure that workers are registered and have sufficient resources
[2025-03-21T13:39:20.581+0000] {job.py:219} ERROR - Job heartbeat got an exception
Traceback (most recent call last):
  File "/home/airflow/.local/lib/python3.8/site-packages/sqlalchemy/engine/base.py", line 3371, in _wrap_pool_connect
    return fn()
  File "/home/airflow/.local/lib/python3.8/site-packages/sqlalchemy/pool/base.py", line 327, in connect
    return _ConnectionFairy._checkout(self)
  File "/home/airflow/.local/lib/python3.8/site-packages/sqlalchemy/pool/base.py", line 894, in _checkout
    fairy = _ConnectionRecord.checkout(pool)
  File "/home/airflow/.local/lib/python3.8/site-packages/sqlalchemy/pool/base.py", line 493, in checkout
    rec = pool._do_get()
  File "/home/airflow/.local/lib/python3.8/site-packages/sqlalchemy/pool/impl.py", line 256, in _do_get
    return self._create_connection()
  File "/home/airflow/.local/lib/python3.8/site-packages/sqlalchemy/pool/base.py", line 273, in _create_connection
    return _ConnectionRecord(self)
  File "/home/airflow/.local/lib/python3.8/site-packages/sqlalchemy/pool/base.py", line 388, in __init__
    self.__connect()
  File "/home/airflow/.local/lib/python3.8/site-packages/sqlalchemy/pool/base.py", line 691, in __connect
    pool.logger.debug("Error on connect(): %s", e)
  File "/home/airflow/.local/lib/python3.8/site-packages/sqlalchemy/util/langhelpers.py", line 70, in __exit__
    compat.raise_(
  File "/home/airflow/.local/lib/python3.8/site-packages/sqlalchemy/util/compat.py", line 211, in raise_
    raise exception
  File "/home/airflow/.local/lib/python3.8/site-packages/sqlalchemy/pool/base.py", line 686, in __connect
    self.dbapi_connection = connection = pool._invoke_creator(self)
  File "/home/airflow/.local/lib/python3.8/site-packages/sqlalchemy/engine/create.py", line 574, in connect
    return dialect.connect(*cargs, **cparams)
  File "/home/airflow/.local/lib/python3.8/site-packages/sqlalchemy/engine/default.py", line 598, in connect
    return self.dbapi.connect(*cargs, **cparams)
  File "/home/airflow/.local/lib/python3.8/site-packages/psycopg2/__init__.py", line 122, in connect
    conn = _connect(dsn, connection_factory=connection_factory, **kwasync)
psycopg2.OperationalError: could not translate host name "postgres" to address: Temporary failure in name resolution


The above exception was the direct cause of the following exception:

Traceback (most recent call last):
  File "/home/airflow/.local/lib/python3.8/site-packages/airflow/jobs/job.py", line 190, in heartbeat
    session.merge(self)
  File "/home/airflow/.local/lib/python3.8/site-packages/sqlalchemy/orm/session.py", line 3056, in merge
    return self._merge(
  File "/home/airflow/.local/lib/python3.8/site-packages/sqlalchemy/orm/session.py", line 3136, in _merge
    merged = self.get(
  File "/home/airflow/.local/lib/python3.8/site-packages/sqlalchemy/orm/session.py", line 2853, in get
    return self._get_impl(
  File "/home/airflow/.local/lib/python3.8/site-packages/sqlalchemy/orm/session.py", line 2975, in _get_impl
    return db_load_fn(
  File "/home/airflow/.local/lib/python3.8/site-packages/sqlalchemy/orm/loading.py", line 530, in load_on_pk_identity
    session.execute(
  File "/home/airflow/.local/lib/python3.8/site-packages/sqlalchemy/orm/session.py", line 1716, in execute
    conn = self._connection_for_bind(bind)
  File "/home/airflow/.local/lib/python3.8/site-packages/sqlalchemy/orm/session.py", line 1555, in _connection_for_bind
    return self._transaction._connection_for_bind(
  File "/home/airflow/.local/lib/python3.8/site-packages/sqlalchemy/orm/session.py", line 750, in _connection_for_bind
    conn = bind.connect()
  File "/home/airflow/.local/lib/python3.8/site-packages/sqlalchemy/future/engine.py", line 406, in connect
    return super(Engine, self).connect()
  File "/home/airflow/.local/lib/python3.8/site-packages/sqlalchemy/engine/base.py", line 3325, in connect
    return self._connection_cls(self, close_with_result=close_with_result)
  File "/home/airflow/.local/lib/python3.8/site-packages/sqlalchemy/engine/base.py", line 96, in __init__
    else engine.raw_connection()
  File "/home/airflow/.local/lib/python3.8/site-packages/sqlalchemy/engine/base.py", line 3404, in raw_connection
    return self._wrap_pool_connect(self.pool.connect, _connection)
  File "/home/airflow/.local/lib/python3.8/site-packages/sqlalchemy/engine/base.py", line 3374, in _wrap_pool_connect
    Connection._handle_dbapi_exception_noconnection(
  File "/home/airflow/.local/lib/python3.8/site-packages/sqlalchemy/engine/base.py", line 2208, in _handle_dbapi_exception_noconnection
    util.raise_(
  File "/home/airflow/.local/lib/python3.8/site-packages/sqlalchemy/util/compat.py", line 211, in raise_
    raise exception
  File "/home/airflow/.local/lib/python3.8/site-packages/sqlalchemy/engine/base.py", line 3371, in _wrap_pool_connect
    return fn()
  File "/home/airflow/.local/lib/python3.8/site-packages/sqlalchemy/pool/base.py", line 327, in connect
    return _ConnectionFairy._checkout(self)
  File "/home/airflow/.local/lib/python3.8/site-packages/sqlalchemy/pool/base.py", line 894, in _checkout
    fairy = _ConnectionRecord.checkout(pool)
  File "/home/airflow/.local/lib/python3.8/site-packages/sqlalchemy/pool/base.py", line 493, in checkout
    rec = pool._do_get()
  File "/home/airflow/.local/lib/python3.8/site-packages/sqlalchemy/pool/impl.py", line 256, in _do_get
    return self._create_connection()
  File "/home/airflow/.local/lib/python3.8/site-packages/sqlalchemy/pool/base.py", line 273, in _create_connection
    return _ConnectionRecord(self)
  File "/home/airflow/.local/lib/python3.8/site-packages/sqlalchemy/pool/base.py", line 388, in __init__
    self.__connect()
  File "/home/airflow/.local/lib/python3.8/site-packages/sqlalchemy/pool/base.py", line 691, in __connect
    pool.logger.debug("Error on connect(): %s", e)
  File "/home/airflow/.local/lib/python3.8/site-packages/sqlalchemy/util/langhelpers.py", line 70, in __exit__
    compat.raise_(
  File "/home/airflow/.local/lib/python3.8/site-packages/sqlalchemy/util/compat.py", line 211, in raise_
    raise exception
  File "/home/airflow/.local/lib/python3.8/site-packages/sqlalchemy/pool/base.py", line 686, in __connect
    self.dbapi_connection = connection = pool._invoke_creator(self)
  File "/home/airflow/.local/lib/python3.8/site-packages/sqlalchemy/engine/create.py", line 574, in connect
    return dialect.connect(*cargs, **cparams)
  File "/home/airflow/.local/lib/python3.8/site-packages/sqlalchemy/engine/default.py", line 598, in connect
    return self.dbapi.connect(*cargs, **cparams)
  File "/home/airflow/.local/lib/python3.8/site-packages/psycopg2/__init__.py", line 122, in connect
    conn = _connect(dsn, connection_factory=connection_factory, **kwasync)
sqlalchemy.exc.OperationalError: (psycopg2.OperationalError) could not translate host name "postgres" to address: Temporary failure in name resolution

(Background on this error at: https://sqlalche.me/e/14/e3q8)
[2025-03-21T13:39:44.460+0000] {job.py:219} ERROR - Job heartbeat got an exception
Traceback (most recent call last):
  File "/home/airflow/.local/lib/python3.8/site-packages/sqlalchemy/engine/base.py", line 3371, in _wrap_pool_connect
    return fn()
  File "/home/airflow/.local/lib/python3.8/site-packages/sqlalchemy/pool/base.py", line 327, in connect
    return _ConnectionFairy._checkout(self)
  File "/home/airflow/.local/lib/python3.8/site-packages/sqlalchemy/pool/base.py", line 894, in _checkout
    fairy = _ConnectionRecord.checkout(pool)
  File "/home/airflow/.local/lib/python3.8/site-packages/sqlalchemy/pool/base.py", line 493, in checkout
    rec = pool._do_get()
  File "/home/airflow/.local/lib/python3.8/site-packages/sqlalchemy/pool/impl.py", line 256, in _do_get
    return self._create_connection()
  File "/home/airflow/.local/lib/python3.8/site-packages/sqlalchemy/pool/base.py", line 273, in _create_connection
    return _ConnectionRecord(self)
  File "/home/airflow/.local/lib/python3.8/site-packages/sqlalchemy/pool/base.py", line 388, in __init__
    self.__connect()
  File "/home/airflow/.local/lib/python3.8/site-packages/sqlalchemy/pool/base.py", line 691, in __connect
    pool.logger.debug("Error on connect(): %s", e)
  File "/home/airflow/.local/lib/python3.8/site-packages/sqlalchemy/util/langhelpers.py", line 70, in __exit__
    compat.raise_(
  File "/home/airflow/.local/lib/python3.8/site-packages/sqlalchemy/util/compat.py", line 211, in raise_
    raise exception
  File "/home/airflow/.local/lib/python3.8/site-packages/sqlalchemy/pool/base.py", line 686, in __connect
    self.dbapi_connection = connection = pool._invoke_creator(self)
  File "/home/airflow/.local/lib/python3.8/site-packages/sqlalchemy/engine/create.py", line 574, in connect
    return dialect.connect(*cargs, **cparams)
  File "/home/airflow/.local/lib/python3.8/site-packages/sqlalchemy/engine/default.py", line 598, in connect
    return self.dbapi.connect(*cargs, **cparams)
  File "/home/airflow/.local/lib/python3.8/site-packages/psycopg2/__init__.py", line 122, in connect
    conn = _connect(dsn, connection_factory=connection_factory, **kwasync)
psycopg2.OperationalError: could not translate host name "postgres" to address: Temporary failure in name resolution


The above exception was the direct cause of the following exception:

Traceback (most recent call last):
  File "/home/airflow/.local/lib/python3.8/site-packages/airflow/jobs/job.py", line 190, in heartbeat
    session.merge(self)
  File "/home/airflow/.local/lib/python3.8/site-packages/sqlalchemy/orm/session.py", line 3056, in merge
    return self._merge(
  File "/home/airflow/.local/lib/python3.8/site-packages/sqlalchemy/orm/session.py", line 3136, in _merge
    merged = self.get(
  File "/home/airflow/.local/lib/python3.8/site-packages/sqlalchemy/orm/session.py", line 2853, in get
    return self._get_impl(
  File "/home/airflow/.local/lib/python3.8/site-packages/sqlalchemy/orm/session.py", line 2975, in _get_impl
    return db_load_fn(
  File "/home/airflow/.local/lib/python3.8/site-packages/sqlalchemy/orm/loading.py", line 530, in load_on_pk_identity
    session.execute(
  File "/home/airflow/.local/lib/python3.8/site-packages/sqlalchemy/orm/session.py", line 1716, in execute
    conn = self._connection_for_bind(bind)
  File "/home/airflow/.local/lib/python3.8/site-packages/sqlalchemy/orm/session.py", line 1555, in _connection_for_bind
    return self._transaction._connection_for_bind(
  File "/home/airflow/.local/lib/python3.8/site-packages/sqlalchemy/orm/session.py", line 750, in _connection_for_bind
    conn = bind.connect()
  File "/home/airflow/.local/lib/python3.8/site-packages/sqlalchemy/future/engine.py", line 406, in connect
    return super(Engine, self).connect()
  File "/home/airflow/.local/lib/python3.8/site-packages/sqlalchemy/engine/base.py", line 3325, in connect
    return self._connection_cls(self, close_with_result=close_with_result)
  File "/home/airflow/.local/lib/python3.8/site-packages/sqlalchemy/engine/base.py", line 96, in __init__
    else engine.raw_connection()
  File "/home/airflow/.local/lib/python3.8/site-packages/sqlalchemy/engine/base.py", line 3404, in raw_connection
    return self._wrap_pool_connect(self.pool.connect, _connection)
  File "/home/airflow/.local/lib/python3.8/site-packages/sqlalchemy/engine/base.py", line 3374, in _wrap_pool_connect
    Connection._handle_dbapi_exception_noconnection(
  File "/home/airflow/.local/lib/python3.8/site-packages/sqlalchemy/engine/base.py", line 2208, in _handle_dbapi_exception_noconnection
    util.raise_(
  File "/home/airflow/.local/lib/python3.8/site-packages/sqlalchemy/util/compat.py", line 211, in raise_
    raise exception
  File "/home/airflow/.local/lib/python3.8/site-packages/sqlalchemy/engine/base.py", line 3371, in _wrap_pool_connect
    return fn()
  File "/home/airflow/.local/lib/python3.8/site-packages/sqlalchemy/pool/base.py", line 327, in connect
    return _ConnectionFairy._checkout(self)
  File "/home/airflow/.local/lib/python3.8/site-packages/sqlalchemy/pool/base.py", line 894, in _checkout
    fairy = _ConnectionRecord.checkout(pool)
  File "/home/airflow/.local/lib/python3.8/site-packages/sqlalchemy/pool/base.py", line 493, in checkout
    rec = pool._do_get()
  File "/home/airflow/.local/lib/python3.8/site-packages/sqlalchemy/pool/impl.py", line 256, in _do_get
    return self._create_connection()
  File "/home/airflow/.local/lib/python3.8/site-packages/sqlalchemy/pool/base.py", line 273, in _create_connection
    return _ConnectionRecord(self)
  File "/home/airflow/.local/lib/python3.8/site-packages/sqlalchemy/pool/base.py", line 388, in __init__
    self.__connect()
  File "/home/airflow/.local/lib/python3.8/site-packages/sqlalchemy/pool/base.py", line 691, in __connect
    pool.logger.debug("Error on connect(): %s", e)
  File "/home/airflow/.local/lib/python3.8/site-packages/sqlalchemy/util/langhelpers.py", line 70, in __exit__
    compat.raise_(
  File "/home/airflow/.local/lib/python3.8/site-packages/sqlalchemy/util/compat.py", line 211, in raise_
    raise exception
  File "/home/airflow/.local/lib/python3.8/site-packages/sqlalchemy/pool/base.py", line 686, in __connect
    self.dbapi_connection = connection = pool._invoke_creator(self)
  File "/home/airflow/.local/lib/python3.8/site-packages/sqlalchemy/engine/create.py", line 574, in connect
    return dialect.connect(*cargs, **cparams)
  File "/home/airflow/.local/lib/python3.8/site-packages/sqlalchemy/engine/default.py", line 598, in connect
    return self.dbapi.connect(*cargs, **cparams)
  File "/home/airflow/.local/lib/python3.8/site-packages/psycopg2/__init__.py", line 122, in connect
    conn = _connect(dsn, connection_factory=connection_factory, **kwasync)
sqlalchemy.exc.OperationalError: (psycopg2.OperationalError) could not translate host name "postgres" to address: Temporary failure in name resolution

(Background on this error at: https://sqlalche.me/e/14/e3q8)
[2025-03-21T13:40:04.608+0000] {job.py:219} ERROR - Job heartbeat got an exception
Traceback (most recent call last):
  File "/home/airflow/.local/lib/python3.8/site-packages/sqlalchemy/engine/base.py", line 3371, in _wrap_pool_connect
    return fn()
  File "/home/airflow/.local/lib/python3.8/site-packages/sqlalchemy/pool/base.py", line 327, in connect
    return _ConnectionFairy._checkout(self)
  File "/home/airflow/.local/lib/python3.8/site-packages/sqlalchemy/pool/base.py", line 894, in _checkout
    fairy = _ConnectionRecord.checkout(pool)
  File "/home/airflow/.local/lib/python3.8/site-packages/sqlalchemy/pool/base.py", line 493, in checkout
    rec = pool._do_get()
  File "/home/airflow/.local/lib/python3.8/site-packages/sqlalchemy/pool/impl.py", line 256, in _do_get
    return self._create_connection()
  File "/home/airflow/.local/lib/python3.8/site-packages/sqlalchemy/pool/base.py", line 273, in _create_connection
    return _ConnectionRecord(self)
  File "/home/airflow/.local/lib/python3.8/site-packages/sqlalchemy/pool/base.py", line 388, in __init__
    self.__connect()
  File "/home/airflow/.local/lib/python3.8/site-packages/sqlalchemy/pool/base.py", line 691, in __connect
    pool.logger.debug("Error on connect(): %s", e)
  File "/home/airflow/.local/lib/python3.8/site-packages/sqlalchemy/util/langhelpers.py", line 70, in __exit__
    compat.raise_(
  File "/home/airflow/.local/lib/python3.8/site-packages/sqlalchemy/util/compat.py", line 211, in raise_
    raise exception
  File "/home/airflow/.local/lib/python3.8/site-packages/sqlalchemy/pool/base.py", line 686, in __connect
    self.dbapi_connection = connection = pool._invoke_creator(self)
  File "/home/airflow/.local/lib/python3.8/site-packages/sqlalchemy/engine/create.py", line 574, in connect
    return dialect.connect(*cargs, **cparams)
  File "/home/airflow/.local/lib/python3.8/site-packages/sqlalchemy/engine/default.py", line 598, in connect
    return self.dbapi.connect(*cargs, **cparams)
  File "/home/airflow/.local/lib/python3.8/site-packages/psycopg2/__init__.py", line 122, in connect
    conn = _connect(dsn, connection_factory=connection_factory, **kwasync)
psycopg2.OperationalError: could not translate host name "postgres" to address: Temporary failure in name resolution


The above exception was the direct cause of the following exception:

Traceback (most recent call last):
  File "/home/airflow/.local/lib/python3.8/site-packages/airflow/jobs/job.py", line 190, in heartbeat
    session.merge(self)
  File "/home/airflow/.local/lib/python3.8/site-packages/sqlalchemy/orm/session.py", line 3056, in merge
    return self._merge(
  File "/home/airflow/.local/lib/python3.8/site-packages/sqlalchemy/orm/session.py", line 3136, in _merge
    merged = self.get(
  File "/home/airflow/.local/lib/python3.8/site-packages/sqlalchemy/orm/session.py", line 2853, in get
    return self._get_impl(
  File "/home/airflow/.local/lib/python3.8/site-packages/sqlalchemy/orm/session.py", line 2975, in _get_impl
    return db_load_fn(
  File "/home/airflow/.local/lib/python3.8/site-packages/sqlalchemy/orm/loading.py", line 530, in load_on_pk_identity
    session.execute(
  File "/home/airflow/.local/lib/python3.8/site-packages/sqlalchemy/orm/session.py", line 1716, in execute
    conn = self._connection_for_bind(bind)
  File "/home/airflow/.local/lib/python3.8/site-packages/sqlalchemy/orm/session.py", line 1555, in _connection_for_bind
    return self._transaction._connection_for_bind(
  File "/home/airflow/.local/lib/python3.8/site-packages/sqlalchemy/orm/session.py", line 750, in _connection_for_bind
    conn = bind.connect()
  File "/home/airflow/.local/lib/python3.8/site-packages/sqlalchemy/future/engine.py", line 406, in connect
    return super(Engine, self).connect()
  File "/home/airflow/.local/lib/python3.8/site-packages/sqlalchemy/engine/base.py", line 3325, in connect
    return self._connection_cls(self, close_with_result=close_with_result)
  File "/home/airflow/.local/lib/python3.8/site-packages/sqlalchemy/engine/base.py", line 96, in __init__
    else engine.raw_connection()
  File "/home/airflow/.local/lib/python3.8/site-packages/sqlalchemy/engine/base.py", line 3404, in raw_connection
    return self._wrap_pool_connect(self.pool.connect, _connection)
  File "/home/airflow/.local/lib/python3.8/site-packages/sqlalchemy/engine/base.py", line 3374, in _wrap_pool_connect
    Connection._handle_dbapi_exception_noconnection(
  File "/home/airflow/.local/lib/python3.8/site-packages/sqlalchemy/engine/base.py", line 2208, in _handle_dbapi_exception_noconnection
    util.raise_(
  File "/home/airflow/.local/lib/python3.8/site-packages/sqlalchemy/util/compat.py", line 211, in raise_
    raise exception
  File "/home/airflow/.local/lib/python3.8/site-packages/sqlalchemy/engine/base.py", line 3371, in _wrap_pool_connect
    return fn()
  File "/home/airflow/.local/lib/python3.8/site-packages/sqlalchemy/pool/base.py", line 327, in connect
    return _ConnectionFairy._checkout(self)
  File "/home/airflow/.local/lib/python3.8/site-packages/sqlalchemy/pool/base.py", line 894, in _checkout
    fairy = _ConnectionRecord.checkout(pool)
  File "/home/airflow/.local/lib/python3.8/site-packages/sqlalchemy/pool/base.py", line 493, in checkout
    rec = pool._do_get()
  File "/home/airflow/.local/lib/python3.8/site-packages/sqlalchemy/pool/impl.py", line 256, in _do_get
    return self._create_connection()
  File "/home/airflow/.local/lib/python3.8/site-packages/sqlalchemy/pool/base.py", line 273, in _create_connection
    return _ConnectionRecord(self)
  File "/home/airflow/.local/lib/python3.8/site-packages/sqlalchemy/pool/base.py", line 388, in __init__
    self.__connect()
  File "/home/airflow/.local/lib/python3.8/site-packages/sqlalchemy/pool/base.py", line 691, in __connect
    pool.logger.debug("Error on connect(): %s", e)
  File "/home/airflow/.local/lib/python3.8/site-packages/sqlalchemy/util/langhelpers.py", line 70, in __exit__
    compat.raise_(
  File "/home/airflow/.local/lib/python3.8/site-packages/sqlalchemy/util/compat.py", line 211, in raise_
    raise exception
  File "/home/airflow/.local/lib/python3.8/site-packages/sqlalchemy/pool/base.py", line 686, in __connect
    self.dbapi_connection = connection = pool._invoke_creator(self)
  File "/home/airflow/.local/lib/python3.8/site-packages/sqlalchemy/engine/create.py", line 574, in connect
    return dialect.connect(*cargs, **cparams)
  File "/home/airflow/.local/lib/python3.8/site-packages/sqlalchemy/engine/default.py", line 598, in connect
    return self.dbapi.connect(*cargs, **cparams)
  File "/home/airflow/.local/lib/python3.8/site-packages/psycopg2/__init__.py", line 122, in connect
    conn = _connect(dsn, connection_factory=connection_factory, **kwasync)
sqlalchemy.exc.OperationalError: (psycopg2.OperationalError) could not translate host name "postgres" to address: Temporary failure in name resolution

(Background on this error at: https://sqlalche.me/e/14/e3q8)
[2025-03-21T13:40:48.341+0000] {subprocess.py:93} INFO - 25/03/21 13:39:08 WARN TaskSchedulerImpl: Initial job has not accepted any resources; check your cluster UI to ensure that workers are registered and have sufficient resources
[2025-03-21T13:40:48.363+0000] {subprocess.py:93} INFO - 25/03/21 13:39:24 WARN TaskSchedulerImpl: Initial job has not accepted any resources; check your cluster UI to ensure that workers are registered and have sufficient resources
[2025-03-21T13:40:48.364+0000] {subprocess.py:93} INFO - 25/03/21 13:39:39 WARN TaskSchedulerImpl: Initial job has not accepted any resources; check your cluster UI to ensure that workers are registered and have sufficient resources
[2025-03-21T13:40:48.365+0000] {subprocess.py:93} INFO - 25/03/21 13:39:53 WARN TaskSchedulerImpl: Initial job has not accepted any resources; check your cluster UI to ensure that workers are registered and have sufficient resources
[2025-03-21T13:40:48.366+0000] {subprocess.py:93} INFO - 25/03/21 13:40:09 WARN TaskSchedulerImpl: Initial job has not accepted any resources; check your cluster UI to ensure that workers are registered and have sufficient resources
[2025-03-21T13:40:48.369+0000] {subprocess.py:93} INFO - 25/03/21 13:40:24 WARN TaskSchedulerImpl: Initial job has not accepted any resources; check your cluster UI to ensure that workers are registered and have sufficient resources
[2025-03-21T13:40:48.370+0000] {subprocess.py:93} INFO - 25/03/21 13:40:41 WARN TaskSchedulerImpl: Initial job has not accepted any resources; check your cluster UI to ensure that workers are registered and have sufficient resources
[2025-03-21T13:40:48.371+0000] {subprocess.py:93} INFO - 25/03/21 13:40:48 INFO AsyncEventQueue: Process of event SparkListenerExecutorMetricsUpdate(driver,WrappedArray(),Map((-1,-1) -> org.apache.spark.executor.ExecutorMetrics@7a287a7e)) by listener AppStatusListener took 4.717884214s.
[2025-03-21T13:40:54.028+0000] {subprocess.py:93} INFO - 25/03/21 13:40:54 WARN TaskSchedulerImpl: Initial job has not accepted any resources; check your cluster UI to ensure that workers are registered and have sufficient resources
[2025-03-21T13:41:09.021+0000] {subprocess.py:93} INFO - 25/03/21 13:41:08 WARN TaskSchedulerImpl: Initial job has not accepted any resources; check your cluster UI to ensure that workers are registered and have sufficient resources
[2025-03-21T13:41:23.795+0000] {subprocess.py:93} INFO - 25/03/21 13:41:23 WARN TaskSchedulerImpl: Initial job has not accepted any resources; check your cluster UI to ensure that workers are registered and have sufficient resources
[2025-03-21T13:41:38.786+0000] {subprocess.py:93} INFO - 25/03/21 13:41:38 WARN TaskSchedulerImpl: Initial job has not accepted any resources; check your cluster UI to ensure that workers are registered and have sufficient resources
[2025-03-21T13:41:53.775+0000] {subprocess.py:93} INFO - 25/03/21 13:41:53 WARN TaskSchedulerImpl: Initial job has not accepted any resources; check your cluster UI to ensure that workers are registered and have sufficient resources
[2025-03-21T13:42:08.778+0000] {subprocess.py:93} INFO - 25/03/21 13:42:08 WARN TaskSchedulerImpl: Initial job has not accepted any resources; check your cluster UI to ensure that workers are registered and have sufficient resources
[2025-03-21T13:42:23.813+0000] {subprocess.py:93} INFO - 25/03/21 13:42:23 WARN TaskSchedulerImpl: Initial job has not accepted any resources; check your cluster UI to ensure that workers are registered and have sufficient resources
[2025-03-21T13:42:38.776+0000] {subprocess.py:93} INFO - 25/03/21 13:42:38 WARN TaskSchedulerImpl: Initial job has not accepted any resources; check your cluster UI to ensure that workers are registered and have sufficient resources
[2025-03-21T13:42:53.791+0000] {subprocess.py:93} INFO - 25/03/21 13:42:53 WARN TaskSchedulerImpl: Initial job has not accepted any resources; check your cluster UI to ensure that workers are registered and have sufficient resources
[2025-03-21T13:43:17.149+0000] {job.py:219} ERROR - Job heartbeat got an exception
Traceback (most recent call last):
  File "/home/airflow/.local/lib/python3.8/site-packages/sqlalchemy/engine/base.py", line 3371, in _wrap_pool_connect
    return fn()
  File "/home/airflow/.local/lib/python3.8/site-packages/sqlalchemy/pool/base.py", line 327, in connect
    return _ConnectionFairy._checkout(self)
  File "/home/airflow/.local/lib/python3.8/site-packages/sqlalchemy/pool/base.py", line 894, in _checkout
    fairy = _ConnectionRecord.checkout(pool)
  File "/home/airflow/.local/lib/python3.8/site-packages/sqlalchemy/pool/base.py", line 493, in checkout
    rec = pool._do_get()
  File "/home/airflow/.local/lib/python3.8/site-packages/sqlalchemy/pool/impl.py", line 256, in _do_get
    return self._create_connection()
  File "/home/airflow/.local/lib/python3.8/site-packages/sqlalchemy/pool/base.py", line 273, in _create_connection
    return _ConnectionRecord(self)
  File "/home/airflow/.local/lib/python3.8/site-packages/sqlalchemy/pool/base.py", line 388, in __init__
    self.__connect()
  File "/home/airflow/.local/lib/python3.8/site-packages/sqlalchemy/pool/base.py", line 691, in __connect
    pool.logger.debug("Error on connect(): %s", e)
  File "/home/airflow/.local/lib/python3.8/site-packages/sqlalchemy/util/langhelpers.py", line 70, in __exit__
    compat.raise_(
  File "/home/airflow/.local/lib/python3.8/site-packages/sqlalchemy/util/compat.py", line 211, in raise_
    raise exception
  File "/home/airflow/.local/lib/python3.8/site-packages/sqlalchemy/pool/base.py", line 686, in __connect
    self.dbapi_connection = connection = pool._invoke_creator(self)
  File "/home/airflow/.local/lib/python3.8/site-packages/sqlalchemy/engine/create.py", line 574, in connect
    return dialect.connect(*cargs, **cparams)
  File "/home/airflow/.local/lib/python3.8/site-packages/sqlalchemy/engine/default.py", line 598, in connect
    return self.dbapi.connect(*cargs, **cparams)
  File "/home/airflow/.local/lib/python3.8/site-packages/psycopg2/__init__.py", line 122, in connect
    conn = _connect(dsn, connection_factory=connection_factory, **kwasync)
psycopg2.OperationalError: could not translate host name "postgres" to address: Temporary failure in name resolution


The above exception was the direct cause of the following exception:

Traceback (most recent call last):
  File "/home/airflow/.local/lib/python3.8/site-packages/airflow/jobs/job.py", line 190, in heartbeat
    session.merge(self)
  File "/home/airflow/.local/lib/python3.8/site-packages/sqlalchemy/orm/session.py", line 3056, in merge
    return self._merge(
  File "/home/airflow/.local/lib/python3.8/site-packages/sqlalchemy/orm/session.py", line 3136, in _merge
    merged = self.get(
  File "/home/airflow/.local/lib/python3.8/site-packages/sqlalchemy/orm/session.py", line 2853, in get
    return self._get_impl(
  File "/home/airflow/.local/lib/python3.8/site-packages/sqlalchemy/orm/session.py", line 2975, in _get_impl
    return db_load_fn(
  File "/home/airflow/.local/lib/python3.8/site-packages/sqlalchemy/orm/loading.py", line 530, in load_on_pk_identity
    session.execute(
  File "/home/airflow/.local/lib/python3.8/site-packages/sqlalchemy/orm/session.py", line 1716, in execute
    conn = self._connection_for_bind(bind)
  File "/home/airflow/.local/lib/python3.8/site-packages/sqlalchemy/orm/session.py", line 1555, in _connection_for_bind
    return self._transaction._connection_for_bind(
  File "/home/airflow/.local/lib/python3.8/site-packages/sqlalchemy/orm/session.py", line 750, in _connection_for_bind
    conn = bind.connect()
  File "/home/airflow/.local/lib/python3.8/site-packages/sqlalchemy/future/engine.py", line 406, in connect
    return super(Engine, self).connect()
  File "/home/airflow/.local/lib/python3.8/site-packages/sqlalchemy/engine/base.py", line 3325, in connect
    return self._connection_cls(self, close_with_result=close_with_result)
  File "/home/airflow/.local/lib/python3.8/site-packages/sqlalchemy/engine/base.py", line 96, in __init__
    else engine.raw_connection()
  File "/home/airflow/.local/lib/python3.8/site-packages/sqlalchemy/engine/base.py", line 3404, in raw_connection
    return self._wrap_pool_connect(self.pool.connect, _connection)
  File "/home/airflow/.local/lib/python3.8/site-packages/sqlalchemy/engine/base.py", line 3374, in _wrap_pool_connect
    Connection._handle_dbapi_exception_noconnection(
  File "/home/airflow/.local/lib/python3.8/site-packages/sqlalchemy/engine/base.py", line 2208, in _handle_dbapi_exception_noconnection
    util.raise_(
  File "/home/airflow/.local/lib/python3.8/site-packages/sqlalchemy/util/compat.py", line 211, in raise_
    raise exception
  File "/home/airflow/.local/lib/python3.8/site-packages/sqlalchemy/engine/base.py", line 3371, in _wrap_pool_connect
    return fn()
  File "/home/airflow/.local/lib/python3.8/site-packages/sqlalchemy/pool/base.py", line 327, in connect
    return _ConnectionFairy._checkout(self)
  File "/home/airflow/.local/lib/python3.8/site-packages/sqlalchemy/pool/base.py", line 894, in _checkout
    fairy = _ConnectionRecord.checkout(pool)
  File "/home/airflow/.local/lib/python3.8/site-packages/sqlalchemy/pool/base.py", line 493, in checkout
    rec = pool._do_get()
  File "/home/airflow/.local/lib/python3.8/site-packages/sqlalchemy/pool/impl.py", line 256, in _do_get
    return self._create_connection()
  File "/home/airflow/.local/lib/python3.8/site-packages/sqlalchemy/pool/base.py", line 273, in _create_connection
    return _ConnectionRecord(self)
  File "/home/airflow/.local/lib/python3.8/site-packages/sqlalchemy/pool/base.py", line 388, in __init__
    self.__connect()
  File "/home/airflow/.local/lib/python3.8/site-packages/sqlalchemy/pool/base.py", line 691, in __connect
    pool.logger.debug("Error on connect(): %s", e)
  File "/home/airflow/.local/lib/python3.8/site-packages/sqlalchemy/util/langhelpers.py", line 70, in __exit__
    compat.raise_(
  File "/home/airflow/.local/lib/python3.8/site-packages/sqlalchemy/util/compat.py", line 211, in raise_
    raise exception
  File "/home/airflow/.local/lib/python3.8/site-packages/sqlalchemy/pool/base.py", line 686, in __connect
    self.dbapi_connection = connection = pool._invoke_creator(self)
  File "/home/airflow/.local/lib/python3.8/site-packages/sqlalchemy/engine/create.py", line 574, in connect
    return dialect.connect(*cargs, **cparams)
  File "/home/airflow/.local/lib/python3.8/site-packages/sqlalchemy/engine/default.py", line 598, in connect
    return self.dbapi.connect(*cargs, **cparams)
  File "/home/airflow/.local/lib/python3.8/site-packages/psycopg2/__init__.py", line 122, in connect
    conn = _connect(dsn, connection_factory=connection_factory, **kwasync)
sqlalchemy.exc.OperationalError: (psycopg2.OperationalError) could not translate host name "postgres" to address: Temporary failure in name resolution

(Background on this error at: https://sqlalche.me/e/14/e3q8)
[2025-03-21T13:43:26.275+0000] {subprocess.py:93} INFO - 25/03/21 13:43:08 WARN TaskSchedulerImpl: Initial job has not accepted any resources; check your cluster UI to ensure that workers are registered and have sufficient resources
[2025-03-21T13:43:26.736+0000] {subprocess.py:97} INFO - Command exited with return code 137
[2025-03-21T13:43:27.122+0000] {taskinstance.py:1935} ERROR - Task failed with exception
Traceback (most recent call last):
  File "/home/airflow/.local/lib/python3.8/site-packages/airflow/operators/bash.py", line 210, in execute
    raise AirflowException(
airflow.exceptions.AirflowException: Bash command failed. The command returned a non-zero exit code 137.
[2025-03-21T13:43:27.256+0000] {taskinstance.py:1398} INFO - Marking task as FAILED. dag_id=transactions_pipeline, task_id=detect_fraud_batch_20250321_131741, execution_date=20250321T133153, start_date=20250321T133431, end_date=20250321T134327
[2025-03-21T13:43:27.741+0000] {logging_mixin.py:151} WARNING - /home/***/.local/lib/python3.8/site-packages/***/utils/email.py:154 RemovedInAirflow3Warning: Fetching SMTP credentials from configuration variables will be deprecated in a future release. Please set credentials using a connection instead.
[2025-03-21T13:43:27.750+0000] {configuration.py:1063} WARNING - section/key [smtp/smtp_user] not found in config
[2025-03-21T13:43:27.752+0000] {email.py:270} INFO - Email alerting: attempt 1
[2025-03-21T13:43:27.832+0000] {configuration.py:1063} WARNING - section/key [smtp/smtp_user] not found in config
[2025-03-21T13:43:27.833+0000] {email.py:270} INFO - Email alerting: attempt 1
[2025-03-21T13:43:27.835+0000] {taskinstance.py:2005} ERROR - Failed to send email to: rabiizahnoune7@gmail.com
Traceback (most recent call last):
  File "/home/airflow/.local/lib/python3.8/site-packages/airflow/models/taskinstance.py", line 1516, in _run_raw_task
    self._execute_task_with_callbacks(context, test_mode, session=session)
  File "/home/airflow/.local/lib/python3.8/site-packages/airflow/models/taskinstance.py", line 1679, in _execute_task_with_callbacks
    result = self._execute_task(context, task_orig)
  File "/home/airflow/.local/lib/python3.8/site-packages/airflow/models/taskinstance.py", line 1742, in _execute_task
    result = execute_callable(context=context, **execute_callable_kwargs)
  File "/home/airflow/.local/lib/python3.8/site-packages/airflow/operators/bash.py", line 210, in execute
    raise AirflowException(
airflow.exceptions.AirflowException: Bash command failed. The command returned a non-zero exit code 137.

During handling of the above exception, another exception occurred:

Traceback (most recent call last):
  File "/home/airflow/.local/lib/python3.8/site-packages/airflow/models/taskinstance.py", line 2418, in email_alert
    send_email(task.email, subject, html_content)
  File "/home/airflow/.local/lib/python3.8/site-packages/airflow/utils/email.py", line 80, in send_email
    return backend(
  File "/home/airflow/.local/lib/python3.8/site-packages/airflow/utils/email.py", line 154, in send_email_smtp
    send_mime_email(e_from=mail_from, e_to=recipients, mime_msg=msg, conn_id=conn_id, dryrun=dryrun)
  File "/home/airflow/.local/lib/python3.8/site-packages/airflow/utils/email.py", line 272, in send_mime_email
    smtp_conn = _get_smtp_connection(smtp_host, smtp_port, smtp_timeout, smtp_ssl)
  File "/home/airflow/.local/lib/python3.8/site-packages/airflow/utils/email.py", line 317, in _get_smtp_connection
    return smtplib.SMTP(host=host, port=port, timeout=timeout)
  File "/usr/local/lib/python3.8/smtplib.py", line 255, in __init__
    (code, msg) = self.connect(host, port)
  File "/usr/local/lib/python3.8/smtplib.py", line 339, in connect
    self.sock = self._get_socket(host, port, self.timeout)
  File "/usr/local/lib/python3.8/smtplib.py", line 310, in _get_socket
    return socket.create_connection((host, port), timeout,
  File "/usr/local/lib/python3.8/socket.py", line 808, in create_connection
    raise err
  File "/usr/local/lib/python3.8/socket.py", line 796, in create_connection
    sock.connect(sa)
ConnectionRefusedError: [Errno 111] Connection refused

During handling of the above exception, another exception occurred:

Traceback (most recent call last):
  File "/home/airflow/.local/lib/python3.8/site-packages/airflow/models/taskinstance.py", line 2003, in handle_failure
    self.email_alert(error, task)
  File "/home/airflow/.local/lib/python3.8/site-packages/airflow/models/taskinstance.py", line 2420, in email_alert
    send_email(task.email, subject, html_content_err)
  File "/home/airflow/.local/lib/python3.8/site-packages/airflow/utils/email.py", line 80, in send_email
    return backend(
  File "/home/airflow/.local/lib/python3.8/site-packages/airflow/utils/email.py", line 154, in send_email_smtp
    send_mime_email(e_from=mail_from, e_to=recipients, mime_msg=msg, conn_id=conn_id, dryrun=dryrun)
  File "/home/airflow/.local/lib/python3.8/site-packages/airflow/utils/email.py", line 272, in send_mime_email
    smtp_conn = _get_smtp_connection(smtp_host, smtp_port, smtp_timeout, smtp_ssl)
  File "/home/airflow/.local/lib/python3.8/site-packages/airflow/utils/email.py", line 317, in _get_smtp_connection
    return smtplib.SMTP(host=host, port=port, timeout=timeout)
  File "/usr/local/lib/python3.8/smtplib.py", line 255, in __init__
    (code, msg) = self.connect(host, port)
  File "/usr/local/lib/python3.8/smtplib.py", line 339, in connect
    self.sock = self._get_socket(host, port, self.timeout)
  File "/usr/local/lib/python3.8/smtplib.py", line 310, in _get_socket
    return socket.create_connection((host, port), timeout,
  File "/usr/local/lib/python3.8/socket.py", line 808, in create_connection
    raise err
  File "/usr/local/lib/python3.8/socket.py", line 796, in create_connection
    sock.connect(sa)
ConnectionRefusedError: [Errno 111] Connection refused
[2025-03-21T13:43:27.923+0000] {configuration.py:1063} WARNING - section/key [smtp/smtp_user] not found in config
[2025-03-21T13:43:27.924+0000] {email.py:270} INFO - Email alerting: attempt 1
[2025-03-21T13:43:27.926+0000] {taskinstance.py:1703} ERROR - Error when executing on_failure_callback callback
Traceback (most recent call last):
  File "/home/airflow/.local/lib/python3.8/site-packages/airflow/models/taskinstance.py", line 1516, in _run_raw_task
    self._execute_task_with_callbacks(context, test_mode, session=session)
  File "/home/airflow/.local/lib/python3.8/site-packages/airflow/models/taskinstance.py", line 1679, in _execute_task_with_callbacks
    result = self._execute_task(context, task_orig)
  File "/home/airflow/.local/lib/python3.8/site-packages/airflow/models/taskinstance.py", line 1742, in _execute_task
    result = execute_callable(context=context, **execute_callable_kwargs)
  File "/home/airflow/.local/lib/python3.8/site-packages/airflow/operators/bash.py", line 210, in execute
    raise AirflowException(
airflow.exceptions.AirflowException: Bash command failed. The command returned a non-zero exit code 137.

During handling of the above exception, another exception occurred:

Traceback (most recent call last):
  File "/home/airflow/.local/lib/python3.8/site-packages/airflow/models/taskinstance.py", line 1700, in _run_finished_callback
    callback(context)
  File "/opt/airflow/dags/fraud_detection_pipeline.py", line 27, in on_failure_callback
    send_email(
  File "/home/airflow/.local/lib/python3.8/site-packages/airflow/utils/email.py", line 80, in send_email
    return backend(
  File "/home/airflow/.local/lib/python3.8/site-packages/airflow/utils/email.py", line 154, in send_email_smtp
    send_mime_email(e_from=mail_from, e_to=recipients, mime_msg=msg, conn_id=conn_id, dryrun=dryrun)
  File "/home/airflow/.local/lib/python3.8/site-packages/airflow/utils/email.py", line 272, in send_mime_email
    smtp_conn = _get_smtp_connection(smtp_host, smtp_port, smtp_timeout, smtp_ssl)
  File "/home/airflow/.local/lib/python3.8/site-packages/airflow/utils/email.py", line 317, in _get_smtp_connection
    return smtplib.SMTP(host=host, port=port, timeout=timeout)
  File "/usr/local/lib/python3.8/smtplib.py", line 255, in __init__
    (code, msg) = self.connect(host, port)
  File "/usr/local/lib/python3.8/smtplib.py", line 339, in connect
    self.sock = self._get_socket(host, port, self.timeout)
  File "/usr/local/lib/python3.8/smtplib.py", line 310, in _get_socket
    return socket.create_connection((host, port), timeout,
  File "/usr/local/lib/python3.8/socket.py", line 808, in create_connection
    raise err
  File "/usr/local/lib/python3.8/socket.py", line 796, in create_connection
    sock.connect(sa)
ConnectionRefusedError: [Errno 111] Connection refused
[2025-03-21T13:43:28.013+0000] {standard_task_runner.py:104} ERROR - Failed to execute job 658 for task detect_fraud_batch_20250321_131741 (Bash command failed. The command returned a non-zero exit code 137.; 2851)
[2025-03-21T13:43:28.066+0000] {local_task_job_runner.py:228} INFO - Task exited with return code 1
[2025-03-21T13:43:28.232+0000] {taskinstance.py:2776} INFO - 0 downstream tasks scheduled from follow-on schedule check
