[2025-03-21T13:25:50.131+0000] {taskinstance.py:1157} INFO - Dependencies all met for dep_context=non-requeueable deps ti=<TaskInstance: transactions_pipeline.create_hive_table_batch_20250321_131507 scheduled__2025-03-21T13:18:54.061628+00:00 [queued]>
[2025-03-21T13:25:50.152+0000] {taskinstance.py:1157} INFO - Dependencies all met for dep_context=requeueable deps ti=<TaskInstance: transactions_pipeline.create_hive_table_batch_20250321_131507 scheduled__2025-03-21T13:18:54.061628+00:00 [queued]>
[2025-03-21T13:25:50.153+0000] {taskinstance.py:1359} INFO - Starting attempt 1 of 1
[2025-03-21T13:25:50.168+0000] {taskinstance.py:1380} INFO - Executing <Task(BashOperator): create_hive_table_batch_20250321_131507> on 2025-03-21 13:18:54.061628+00:00
[2025-03-21T13:25:50.173+0000] {standard_task_runner.py:57} INFO - Started process 1635 to run task
[2025-03-21T13:25:50.177+0000] {standard_task_runner.py:84} INFO - Running: ['***', 'tasks', 'run', 'transactions_pipeline', 'create_hive_table_batch_20250321_131507', 'scheduled__2025-03-21T13:18:54.061628+00:00', '--job-id', '618', '--raw', '--subdir', 'DAGS_FOLDER/fraud_detection_pipeline.py', '--cfg-path', '/tmp/tmpos4z0sw5']
[2025-03-21T13:25:50.182+0000] {standard_task_runner.py:85} INFO - Job 618: Subtask create_hive_table_batch_20250321_131507
[2025-03-21T13:25:50.265+0000] {task_command.py:415} INFO - Running <TaskInstance: transactions_pipeline.create_hive_table_batch_20250321_131507 scheduled__2025-03-21T13:18:54.061628+00:00 [running]> on host 1b7c3466167a
[2025-03-21T13:25:50.414+0000] {taskinstance.py:1660} INFO - Exporting env vars: AIRFLOW_CTX_DAG_EMAIL='rabiizahnoune7@gmail.com' AIRFLOW_CTX_DAG_OWNER='***' AIRFLOW_CTX_DAG_ID='transactions_pipeline' AIRFLOW_CTX_TASK_ID='create_hive_table_batch_20250321_131507' AIRFLOW_CTX_EXECUTION_DATE='2025-03-21T13:18:54.061628+00:00' AIRFLOW_CTX_TRY_NUMBER='1' AIRFLOW_CTX_DAG_RUN_ID='scheduled__2025-03-21T13:18:54.061628+00:00'
[2025-03-21T13:25:50.421+0000] {subprocess.py:63} INFO - Tmp dir root location: /tmp
[2025-03-21T13:25:50.427+0000] {subprocess.py:75} INFO - Running command: ['/bin/bash', '-c', '\n            docker exec hive beeline -u "jdbc:hive2://localhost:10000" --hiveconf hive.exec.dynamic.partition.mode=nonstrict -e "\n            CREATE EXTERNAL TABLE IF NOT EXISTS transactions (\n                transaction_id STRING,\n                date_time STRING,\n                amount DOUBLE,\n                currency STRING,\n                merchant_details STRING,\n                customer_id STRING,\n                transaction_type STRING,\n                location STRING\n            )\n            PARTITIONED BY (batch_id STRING)\n            STORED AS PARQUET;\n            ALTER TABLE transactions ADD IF NOT EXISTS PARTITION (batch_id=\'batch_20250321_131507\') LOCATION \'/data/transactions/transactions_batch_20250321_131507\';"\n            ']
[2025-03-21T13:25:50.449+0000] {subprocess.py:86} INFO - Output:
[2025-03-21T13:26:15.011+0000] {subprocess.py:93} INFO - SLF4J: Class path contains multiple SLF4J bindings.
[2025-03-21T13:26:15.013+0000] {subprocess.py:93} INFO - SLF4J: Found binding in [jar:file:/opt/hive/lib/log4j-slf4j-impl-2.17.1.jar!/org/slf4j/impl/StaticLoggerBinder.class]
[2025-03-21T13:26:15.014+0000] {subprocess.py:93} INFO - SLF4J: Found binding in [jar:file:/opt/hadoop/share/hadoop/common/lib/slf4j-log4j12-1.7.25.jar!/org/slf4j/impl/StaticLoggerBinder.class]
[2025-03-21T13:26:15.015+0000] {subprocess.py:93} INFO - SLF4J: See http://www.slf4j.org/codes.html#multiple_bindings for an explanation.
[2025-03-21T13:26:18.921+0000] {subprocess.py:93} INFO - SLF4J: Actual binding is of type [org.apache.logging.slf4j.Log4jLoggerFactory]
[2025-03-21T13:26:58.554+0000] {subprocess.py:93} INFO - Connecting to jdbc:hive2://localhost:10000
[2025-03-21T13:27:14.591+0000] {job.py:219} ERROR - Job heartbeat got an exception
Traceback (most recent call last):
  File "/home/airflow/.local/lib/python3.8/site-packages/sqlalchemy/engine/base.py", line 3371, in _wrap_pool_connect
    return fn()
  File "/home/airflow/.local/lib/python3.8/site-packages/sqlalchemy/pool/base.py", line 327, in connect
    return _ConnectionFairy._checkout(self)
  File "/home/airflow/.local/lib/python3.8/site-packages/sqlalchemy/pool/base.py", line 894, in _checkout
    fairy = _ConnectionRecord.checkout(pool)
  File "/home/airflow/.local/lib/python3.8/site-packages/sqlalchemy/pool/base.py", line 493, in checkout
    rec = pool._do_get()
  File "/home/airflow/.local/lib/python3.8/site-packages/sqlalchemy/pool/impl.py", line 256, in _do_get
    return self._create_connection()
  File "/home/airflow/.local/lib/python3.8/site-packages/sqlalchemy/pool/base.py", line 273, in _create_connection
    return _ConnectionRecord(self)
  File "/home/airflow/.local/lib/python3.8/site-packages/sqlalchemy/pool/base.py", line 388, in __init__
    self.__connect()
  File "/home/airflow/.local/lib/python3.8/site-packages/sqlalchemy/pool/base.py", line 691, in __connect
    pool.logger.debug("Error on connect(): %s", e)
  File "/home/airflow/.local/lib/python3.8/site-packages/sqlalchemy/util/langhelpers.py", line 70, in __exit__
    compat.raise_(
  File "/home/airflow/.local/lib/python3.8/site-packages/sqlalchemy/util/compat.py", line 211, in raise_
    raise exception
  File "/home/airflow/.local/lib/python3.8/site-packages/sqlalchemy/pool/base.py", line 686, in __connect
    self.dbapi_connection = connection = pool._invoke_creator(self)
  File "/home/airflow/.local/lib/python3.8/site-packages/sqlalchemy/engine/create.py", line 574, in connect
    return dialect.connect(*cargs, **cparams)
  File "/home/airflow/.local/lib/python3.8/site-packages/sqlalchemy/engine/default.py", line 598, in connect
    return self.dbapi.connect(*cargs, **cparams)
  File "/home/airflow/.local/lib/python3.8/site-packages/psycopg2/__init__.py", line 122, in connect
    conn = _connect(dsn, connection_factory=connection_factory, **kwasync)
psycopg2.OperationalError: could not translate host name "postgres" to address: Temporary failure in name resolution


The above exception was the direct cause of the following exception:

Traceback (most recent call last):
  File "/home/airflow/.local/lib/python3.8/site-packages/airflow/jobs/job.py", line 190, in heartbeat
    session.merge(self)
  File "/home/airflow/.local/lib/python3.8/site-packages/sqlalchemy/orm/session.py", line 3056, in merge
    return self._merge(
  File "/home/airflow/.local/lib/python3.8/site-packages/sqlalchemy/orm/session.py", line 3136, in _merge
    merged = self.get(
  File "/home/airflow/.local/lib/python3.8/site-packages/sqlalchemy/orm/session.py", line 2853, in get
    return self._get_impl(
  File "/home/airflow/.local/lib/python3.8/site-packages/sqlalchemy/orm/session.py", line 2975, in _get_impl
    return db_load_fn(
  File "/home/airflow/.local/lib/python3.8/site-packages/sqlalchemy/orm/loading.py", line 530, in load_on_pk_identity
    session.execute(
  File "/home/airflow/.local/lib/python3.8/site-packages/sqlalchemy/orm/session.py", line 1716, in execute
    conn = self._connection_for_bind(bind)
  File "/home/airflow/.local/lib/python3.8/site-packages/sqlalchemy/orm/session.py", line 1555, in _connection_for_bind
    return self._transaction._connection_for_bind(
  File "/home/airflow/.local/lib/python3.8/site-packages/sqlalchemy/orm/session.py", line 750, in _connection_for_bind
    conn = bind.connect()
  File "/home/airflow/.local/lib/python3.8/site-packages/sqlalchemy/future/engine.py", line 406, in connect
    return super(Engine, self).connect()
  File "/home/airflow/.local/lib/python3.8/site-packages/sqlalchemy/engine/base.py", line 3325, in connect
    return self._connection_cls(self, close_with_result=close_with_result)
  File "/home/airflow/.local/lib/python3.8/site-packages/sqlalchemy/engine/base.py", line 96, in __init__
    else engine.raw_connection()
  File "/home/airflow/.local/lib/python3.8/site-packages/sqlalchemy/engine/base.py", line 3404, in raw_connection
    return self._wrap_pool_connect(self.pool.connect, _connection)
  File "/home/airflow/.local/lib/python3.8/site-packages/sqlalchemy/engine/base.py", line 3374, in _wrap_pool_connect
    Connection._handle_dbapi_exception_noconnection(
  File "/home/airflow/.local/lib/python3.8/site-packages/sqlalchemy/engine/base.py", line 2208, in _handle_dbapi_exception_noconnection
    util.raise_(
  File "/home/airflow/.local/lib/python3.8/site-packages/sqlalchemy/util/compat.py", line 211, in raise_
    raise exception
  File "/home/airflow/.local/lib/python3.8/site-packages/sqlalchemy/engine/base.py", line 3371, in _wrap_pool_connect
    return fn()
  File "/home/airflow/.local/lib/python3.8/site-packages/sqlalchemy/pool/base.py", line 327, in connect
    return _ConnectionFairy._checkout(self)
  File "/home/airflow/.local/lib/python3.8/site-packages/sqlalchemy/pool/base.py", line 894, in _checkout
    fairy = _ConnectionRecord.checkout(pool)
  File "/home/airflow/.local/lib/python3.8/site-packages/sqlalchemy/pool/base.py", line 493, in checkout
    rec = pool._do_get()
  File "/home/airflow/.local/lib/python3.8/site-packages/sqlalchemy/pool/impl.py", line 256, in _do_get
    return self._create_connection()
  File "/home/airflow/.local/lib/python3.8/site-packages/sqlalchemy/pool/base.py", line 273, in _create_connection
    return _ConnectionRecord(self)
  File "/home/airflow/.local/lib/python3.8/site-packages/sqlalchemy/pool/base.py", line 388, in __init__
    self.__connect()
  File "/home/airflow/.local/lib/python3.8/site-packages/sqlalchemy/pool/base.py", line 691, in __connect
    pool.logger.debug("Error on connect(): %s", e)
  File "/home/airflow/.local/lib/python3.8/site-packages/sqlalchemy/util/langhelpers.py", line 70, in __exit__
    compat.raise_(
  File "/home/airflow/.local/lib/python3.8/site-packages/sqlalchemy/util/compat.py", line 211, in raise_
    raise exception
  File "/home/airflow/.local/lib/python3.8/site-packages/sqlalchemy/pool/base.py", line 686, in __connect
    self.dbapi_connection = connection = pool._invoke_creator(self)
  File "/home/airflow/.local/lib/python3.8/site-packages/sqlalchemy/engine/create.py", line 574, in connect
    return dialect.connect(*cargs, **cparams)
  File "/home/airflow/.local/lib/python3.8/site-packages/sqlalchemy/engine/default.py", line 598, in connect
    return self.dbapi.connect(*cargs, **cparams)
  File "/home/airflow/.local/lib/python3.8/site-packages/psycopg2/__init__.py", line 122, in connect
    conn = _connect(dsn, connection_factory=connection_factory, **kwasync)
sqlalchemy.exc.OperationalError: (psycopg2.OperationalError) could not translate host name "postgres" to address: Temporary failure in name resolution

(Background on this error at: https://sqlalche.me/e/14/e3q8)
[2025-03-21T13:27:27.194+0000] {subprocess.py:93} INFO - Connected to: Apache Hive (version 3.1.3)
[2025-03-21T13:27:27.196+0000] {subprocess.py:93} INFO - Driver: Hive JDBC (version 3.1.3)
[2025-03-21T13:27:27.198+0000] {subprocess.py:93} INFO - Transaction isolation: TRANSACTION_REPEATABLE_READ
[2025-03-21T13:27:31.022+0000] {subprocess.py:93} INFO - INFO  : Compiling command(queryId=root_20250321132728_f1388bde-7a97-4f40-80ae-71752974e08e): CREATE EXTERNAL TABLE IF NOT EXISTS transactions (
[2025-03-21T13:27:31.025+0000] {subprocess.py:93} INFO -                 transaction_id STRING,
[2025-03-21T13:27:31.027+0000] {subprocess.py:93} INFO -                 date_time STRING,
[2025-03-21T13:27:31.028+0000] {subprocess.py:93} INFO -                 amount DOUBLE,
[2025-03-21T13:27:31.029+0000] {subprocess.py:93} INFO -                 currency STRING,
[2025-03-21T13:27:31.030+0000] {subprocess.py:93} INFO -                 merchant_details STRING,
[2025-03-21T13:27:31.031+0000] {subprocess.py:93} INFO -                 customer_id STRING,
[2025-03-21T13:27:31.032+0000] {subprocess.py:93} INFO -                 transaction_type STRING,
[2025-03-21T13:27:31.033+0000] {subprocess.py:93} INFO -                 location STRING
[2025-03-21T13:27:31.034+0000] {subprocess.py:93} INFO -             )
[2025-03-21T13:27:31.035+0000] {subprocess.py:93} INFO -             PARTITIONED BY (batch_id STRING)
[2025-03-21T13:27:31.114+0000] {subprocess.py:93} INFO -             STORED AS PARQUET
[2025-03-21T13:27:31.122+0000] {subprocess.py:93} INFO - INFO  : Concurrency mode is disabled, not creating a lock manager
[2025-03-21T13:27:31.123+0000] {subprocess.py:93} INFO - INFO  : Semantic Analysis Completed (retrial = false)
[2025-03-21T13:27:31.124+0000] {subprocess.py:93} INFO - INFO  : Returning Hive schema: Schema(fieldSchemas:null, properties:null)
[2025-03-21T13:27:31.125+0000] {subprocess.py:93} INFO - INFO  : Completed compiling command(queryId=root_20250321132728_f1388bde-7a97-4f40-80ae-71752974e08e); Time taken: 2.594 seconds
[2025-03-21T13:27:31.126+0000] {subprocess.py:93} INFO - INFO  : Concurrency mode is disabled, not creating a lock manager
[2025-03-21T13:27:31.129+0000] {subprocess.py:93} INFO - INFO  : Executing command(queryId=root_20250321132728_f1388bde-7a97-4f40-80ae-71752974e08e): CREATE EXTERNAL TABLE IF NOT EXISTS transactions (
[2025-03-21T13:27:31.130+0000] {subprocess.py:93} INFO -                 transaction_id STRING,
[2025-03-21T13:27:31.131+0000] {subprocess.py:93} INFO -                 date_time STRING,
[2025-03-21T13:27:31.131+0000] {subprocess.py:93} INFO -                 amount DOUBLE,
[2025-03-21T13:27:31.132+0000] {subprocess.py:93} INFO -                 currency STRING,
[2025-03-21T13:27:31.132+0000] {subprocess.py:93} INFO -                 merchant_details STRING,
[2025-03-21T13:27:31.132+0000] {subprocess.py:93} INFO -                 customer_id STRING,
[2025-03-21T13:27:31.133+0000] {subprocess.py:93} INFO -                 transaction_type STRING,
[2025-03-21T13:27:31.133+0000] {subprocess.py:93} INFO -                 location STRING
[2025-03-21T13:27:31.134+0000] {subprocess.py:93} INFO -             )
[2025-03-21T13:27:31.134+0000] {subprocess.py:93} INFO -             PARTITIONED BY (batch_id STRING)
[2025-03-21T13:27:31.134+0000] {subprocess.py:93} INFO -             STORED AS PARQUET
[2025-03-21T13:27:31.135+0000] {subprocess.py:93} INFO - INFO  : Completed executing command(queryId=root_20250321132728_f1388bde-7a97-4f40-80ae-71752974e08e); Time taken: 0.022 seconds
[2025-03-21T13:27:31.135+0000] {subprocess.py:93} INFO - INFO  : OK
[2025-03-21T13:27:31.135+0000] {subprocess.py:93} INFO - INFO  : Concurrency mode is disabled, not creating a lock manager
[2025-03-21T13:27:31.136+0000] {subprocess.py:93} INFO - No rows affected (3.487 seconds)
[2025-03-21T13:27:33.011+0000] {subprocess.py:93} INFO - INFO  : Compiling command(queryId=root_20250321132731_9ace41cb-057c-4122-aed9-4e9755af97a0): ALTER TABLE transactions ADD IF NOT EXISTS PARTITION (batch_id='batch_20250321_131507') LOCATION '/data/transactions/transactions_batch_20250321_131507'
[2025-03-21T13:27:33.020+0000] {subprocess.py:93} INFO - INFO  : Concurrency mode is disabled, not creating a lock manager
[2025-03-21T13:27:33.022+0000] {subprocess.py:93} INFO - INFO  : Semantic Analysis Completed (retrial = false)
[2025-03-21T13:27:33.023+0000] {subprocess.py:93} INFO - INFO  : Returning Hive schema: Schema(fieldSchemas:null, properties:null)
[2025-03-21T13:27:33.025+0000] {subprocess.py:93} INFO - INFO  : Completed compiling command(queryId=root_20250321132731_9ace41cb-057c-4122-aed9-4e9755af97a0); Time taken: 0.42 seconds
[2025-03-21T13:27:33.027+0000] {subprocess.py:93} INFO - INFO  : Concurrency mode is disabled, not creating a lock manager
[2025-03-21T13:27:33.028+0000] {subprocess.py:93} INFO - INFO  : Executing command(queryId=root_20250321132731_9ace41cb-057c-4122-aed9-4e9755af97a0): ALTER TABLE transactions ADD IF NOT EXISTS PARTITION (batch_id='batch_20250321_131507') LOCATION '/data/transactions/transactions_batch_20250321_131507'
[2025-03-21T13:27:33.029+0000] {subprocess.py:93} INFO - INFO  : Starting task [Stage-0:DDL] in serial mode
[2025-03-21T13:27:37.950+0000] {subprocess.py:93} INFO - INFO  : Completed executing command(queryId=root_20250321132731_9ace41cb-057c-4122-aed9-4e9755af97a0); Time taken: 5.276 seconds
[2025-03-21T13:27:37.951+0000] {subprocess.py:93} INFO - INFO  : OK
[2025-03-21T13:27:37.952+0000] {subprocess.py:93} INFO - INFO  : Concurrency mode is disabled, not creating a lock manager
[2025-03-21T13:27:37.953+0000] {subprocess.py:93} INFO - No rows affected (6.505 seconds)
[2025-03-21T13:27:38.305+0000] {subprocess.py:93} INFO - Beeline version 3.1.3 by Apache Hive
[2025-03-21T13:27:38.472+0000] {local_task_job_runner.py:294} WARNING - State of this instance has been externally set to removed. Terminating instance.
[2025-03-21T13:27:38.522+0000] {process_utils.py:131} INFO - Sending 15 to group 1635. PIDs of all processes in the group: [1636, 1637, 1635]
[2025-03-21T13:27:38.548+0000] {process_utils.py:86} INFO - Sending the signal 15 to group 1635
[2025-03-21T13:27:38.554+0000] {taskinstance.py:1630} ERROR - Received SIGTERM. Terminating subprocesses.
[2025-03-21T13:27:38.555+0000] {subprocess.py:104} INFO - Sending SIGTERM signal to process group
[2025-03-21T13:27:38.704+0000] {process_utils.py:79} INFO - Process psutil.Process(pid=1636, status='terminated', started='13:25:50') (1636) terminated with exit code None
[2025-03-21T13:27:38.707+0000] {process_utils.py:79} INFO - Process psutil.Process(pid=1637, status='terminated', started='13:25:50') (1637) terminated with exit code None
[2025-03-21T13:27:38.708+0000] {process_utils.py:79} INFO - Process psutil.Process(pid=1635, status='terminated', exitcode=0, started='13:25:50') (1635) terminated with exit code 0
