[2025-03-20T20:25:44.970+0000] {taskinstance.py:1157} INFO - Dependencies all met for dep_context=non-requeueable deps ti=<TaskInstance: transactions_pipeline.copy_to_hdfs scheduled__2025-03-20T19:30:32.992418+00:00 [queued]>
[2025-03-20T20:25:44.989+0000] {taskinstance.py:1157} INFO - Dependencies all met for dep_context=requeueable deps ti=<TaskInstance: transactions_pipeline.copy_to_hdfs scheduled__2025-03-20T19:30:32.992418+00:00 [queued]>
[2025-03-20T20:25:44.990+0000] {taskinstance.py:1359} INFO - Starting attempt 2 of 2
[2025-03-20T20:25:45.010+0000] {taskinstance.py:1380} INFO - Executing <Task(BashOperator): copy_to_hdfs> on 2025-03-20 19:30:32.992418+00:00
[2025-03-20T20:25:45.017+0000] {standard_task_runner.py:57} INFO - Started process 719 to run task
[2025-03-20T20:25:45.021+0000] {standard_task_runner.py:84} INFO - Running: ['***', 'tasks', 'run', 'transactions_pipeline', 'copy_to_hdfs', 'scheduled__2025-03-20T19:30:32.992418+00:00', '--job-id', '408', '--raw', '--subdir', 'DAGS_FOLDER/fraud_detection_pipeline.py', '--cfg-path', '/tmp/tmpqzifbz77']
[2025-03-20T20:25:45.025+0000] {standard_task_runner.py:85} INFO - Job 408: Subtask copy_to_hdfs
[2025-03-20T20:25:45.089+0000] {task_command.py:415} INFO - Running <TaskInstance: transactions_pipeline.copy_to_hdfs scheduled__2025-03-20T19:30:32.992418+00:00 [running]> on host 8c44aa295412
[2025-03-20T20:25:45.227+0000] {taskinstance.py:1660} INFO - Exporting env vars: AIRFLOW_CTX_DAG_EMAIL='rabiizahnoune7@gmail.com' AIRFLOW_CTX_DAG_OWNER='***' AIRFLOW_CTX_DAG_ID='transactions_pipeline' AIRFLOW_CTX_TASK_ID='copy_to_hdfs' AIRFLOW_CTX_EXECUTION_DATE='2025-03-20T19:30:32.992418+00:00' AIRFLOW_CTX_TRY_NUMBER='2' AIRFLOW_CTX_DAG_RUN_ID='scheduled__2025-03-20T19:30:32.992418+00:00'
[2025-03-20T20:25:45.229+0000] {subprocess.py:63} INFO - Tmp dir root location: /tmp
[2025-03-20T20:25:45.231+0000] {subprocess.py:75} INFO - Running command: ['/bin/bash', '-c', '\n        docker exec hive hdfs dfs -mkdir -p /data/transactions/transactions_batch_20250320_144447 &&         docker exec hive hdfs dfs -put -f /data/transactions/transactions_batch_20250320_144447.parquet /data/transactions/transactions_batch_20250320_144447/\n        ']
[2025-03-20T20:25:45.245+0000] {subprocess.py:86} INFO - Output:
[2025-03-20T20:25:45.327+0000] {subprocess.py:93} INFO - Error response from daemon: container 79c704b6c2c373c7d850d9bc8d26cd31fe6146d7221a53c6a61543ed8369f5a4 is not running
[2025-03-20T20:25:45.330+0000] {subprocess.py:97} INFO - Command exited with return code 1
[2025-03-20T20:25:45.349+0000] {taskinstance.py:1935} ERROR - Task failed with exception
Traceback (most recent call last):
  File "/home/airflow/.local/lib/python3.8/site-packages/airflow/operators/bash.py", line 210, in execute
    raise AirflowException(
airflow.exceptions.AirflowException: Bash command failed. The command returned a non-zero exit code 1.
[2025-03-20T20:25:45.360+0000] {taskinstance.py:1398} INFO - Marking task as FAILED. dag_id=transactions_pipeline, task_id=copy_to_hdfs, execution_date=20250320T193032, start_date=20250320T202544, end_date=20250320T202545
[2025-03-20T20:25:45.403+0000] {logging_mixin.py:151} WARNING - /home/***/.local/lib/python3.8/site-packages/***/utils/email.py:154 RemovedInAirflow3Warning: Fetching SMTP credentials from configuration variables will be deprecated in a future release. Please set credentials using a connection instead.
[2025-03-20T20:25:45.405+0000] {configuration.py:1063} WARNING - section/key [smtp/smtp_user] not found in config
[2025-03-20T20:25:45.406+0000] {email.py:270} INFO - Email alerting: attempt 1
[2025-03-20T20:25:45.420+0000] {configuration.py:1063} WARNING - section/key [smtp/smtp_user] not found in config
[2025-03-20T20:25:45.422+0000] {email.py:270} INFO - Email alerting: attempt 1
[2025-03-20T20:25:45.424+0000] {taskinstance.py:2005} ERROR - Failed to send email to: rabiizahnoune7@gmail.com
Traceback (most recent call last):
  File "/home/airflow/.local/lib/python3.8/site-packages/airflow/models/taskinstance.py", line 1516, in _run_raw_task
    self._execute_task_with_callbacks(context, test_mode, session=session)
  File "/home/airflow/.local/lib/python3.8/site-packages/airflow/models/taskinstance.py", line 1679, in _execute_task_with_callbacks
    result = self._execute_task(context, task_orig)
  File "/home/airflow/.local/lib/python3.8/site-packages/airflow/models/taskinstance.py", line 1742, in _execute_task
    result = execute_callable(context=context, **execute_callable_kwargs)
  File "/home/airflow/.local/lib/python3.8/site-packages/airflow/operators/bash.py", line 210, in execute
    raise AirflowException(
airflow.exceptions.AirflowException: Bash command failed. The command returned a non-zero exit code 1.

During handling of the above exception, another exception occurred:

Traceback (most recent call last):
  File "/home/airflow/.local/lib/python3.8/site-packages/airflow/models/taskinstance.py", line 2418, in email_alert
    send_email(task.email, subject, html_content)
  File "/home/airflow/.local/lib/python3.8/site-packages/airflow/utils/email.py", line 80, in send_email
    return backend(
  File "/home/airflow/.local/lib/python3.8/site-packages/airflow/utils/email.py", line 154, in send_email_smtp
    send_mime_email(e_from=mail_from, e_to=recipients, mime_msg=msg, conn_id=conn_id, dryrun=dryrun)
  File "/home/airflow/.local/lib/python3.8/site-packages/airflow/utils/email.py", line 272, in send_mime_email
    smtp_conn = _get_smtp_connection(smtp_host, smtp_port, smtp_timeout, smtp_ssl)
  File "/home/airflow/.local/lib/python3.8/site-packages/airflow/utils/email.py", line 317, in _get_smtp_connection
    return smtplib.SMTP(host=host, port=port, timeout=timeout)
  File "/usr/local/lib/python3.8/smtplib.py", line 255, in __init__
    (code, msg) = self.connect(host, port)
  File "/usr/local/lib/python3.8/smtplib.py", line 339, in connect
    self.sock = self._get_socket(host, port, self.timeout)
  File "/usr/local/lib/python3.8/smtplib.py", line 310, in _get_socket
    return socket.create_connection((host, port), timeout,
  File "/usr/local/lib/python3.8/socket.py", line 808, in create_connection
    raise err
  File "/usr/local/lib/python3.8/socket.py", line 796, in create_connection
    sock.connect(sa)
ConnectionRefusedError: [Errno 111] Connection refused

During handling of the above exception, another exception occurred:

Traceback (most recent call last):
  File "/home/airflow/.local/lib/python3.8/site-packages/airflow/models/taskinstance.py", line 2003, in handle_failure
    self.email_alert(error, task)
  File "/home/airflow/.local/lib/python3.8/site-packages/airflow/models/taskinstance.py", line 2420, in email_alert
    send_email(task.email, subject, html_content_err)
  File "/home/airflow/.local/lib/python3.8/site-packages/airflow/utils/email.py", line 80, in send_email
    return backend(
  File "/home/airflow/.local/lib/python3.8/site-packages/airflow/utils/email.py", line 154, in send_email_smtp
    send_mime_email(e_from=mail_from, e_to=recipients, mime_msg=msg, conn_id=conn_id, dryrun=dryrun)
  File "/home/airflow/.local/lib/python3.8/site-packages/airflow/utils/email.py", line 272, in send_mime_email
    smtp_conn = _get_smtp_connection(smtp_host, smtp_port, smtp_timeout, smtp_ssl)
  File "/home/airflow/.local/lib/python3.8/site-packages/airflow/utils/email.py", line 317, in _get_smtp_connection
    return smtplib.SMTP(host=host, port=port, timeout=timeout)
  File "/usr/local/lib/python3.8/smtplib.py", line 255, in __init__
    (code, msg) = self.connect(host, port)
  File "/usr/local/lib/python3.8/smtplib.py", line 339, in connect
    self.sock = self._get_socket(host, port, self.timeout)
  File "/usr/local/lib/python3.8/smtplib.py", line 310, in _get_socket
    return socket.create_connection((host, port), timeout,
  File "/usr/local/lib/python3.8/socket.py", line 808, in create_connection
    raise err
  File "/usr/local/lib/python3.8/socket.py", line 796, in create_connection
    sock.connect(sa)
ConnectionRefusedError: [Errno 111] Connection refused
[2025-03-20T20:25:45.452+0000] {configuration.py:1063} WARNING - section/key [smtp/smtp_user] not found in config
[2025-03-20T20:25:45.453+0000] {email.py:270} INFO - Email alerting: attempt 1
[2025-03-20T20:25:45.454+0000] {taskinstance.py:1703} ERROR - Error when executing on_failure_callback callback
Traceback (most recent call last):
  File "/home/airflow/.local/lib/python3.8/site-packages/airflow/models/taskinstance.py", line 1516, in _run_raw_task
    self._execute_task_with_callbacks(context, test_mode, session=session)
  File "/home/airflow/.local/lib/python3.8/site-packages/airflow/models/taskinstance.py", line 1679, in _execute_task_with_callbacks
    result = self._execute_task(context, task_orig)
  File "/home/airflow/.local/lib/python3.8/site-packages/airflow/models/taskinstance.py", line 1742, in _execute_task
    result = execute_callable(context=context, **execute_callable_kwargs)
  File "/home/airflow/.local/lib/python3.8/site-packages/airflow/operators/bash.py", line 210, in execute
    raise AirflowException(
airflow.exceptions.AirflowException: Bash command failed. The command returned a non-zero exit code 1.

During handling of the above exception, another exception occurred:

Traceback (most recent call last):
  File "/home/airflow/.local/lib/python3.8/site-packages/airflow/models/taskinstance.py", line 1700, in _run_finished_callback
    callback(context)
  File "/opt/airflow/dags/fraud_detection_pipeline.py", line 27, in on_failure_callback
    send_email(
  File "/home/airflow/.local/lib/python3.8/site-packages/airflow/utils/email.py", line 80, in send_email
    return backend(
  File "/home/airflow/.local/lib/python3.8/site-packages/airflow/utils/email.py", line 154, in send_email_smtp
    send_mime_email(e_from=mail_from, e_to=recipients, mime_msg=msg, conn_id=conn_id, dryrun=dryrun)
  File "/home/airflow/.local/lib/python3.8/site-packages/airflow/utils/email.py", line 272, in send_mime_email
    smtp_conn = _get_smtp_connection(smtp_host, smtp_port, smtp_timeout, smtp_ssl)
  File "/home/airflow/.local/lib/python3.8/site-packages/airflow/utils/email.py", line 317, in _get_smtp_connection
    return smtplib.SMTP(host=host, port=port, timeout=timeout)
  File "/usr/local/lib/python3.8/smtplib.py", line 255, in __init__
    (code, msg) = self.connect(host, port)
  File "/usr/local/lib/python3.8/smtplib.py", line 339, in connect
    self.sock = self._get_socket(host, port, self.timeout)
  File "/usr/local/lib/python3.8/smtplib.py", line 310, in _get_socket
    return socket.create_connection((host, port), timeout,
  File "/usr/local/lib/python3.8/socket.py", line 808, in create_connection
    raise err
  File "/usr/local/lib/python3.8/socket.py", line 796, in create_connection
    sock.connect(sa)
ConnectionRefusedError: [Errno 111] Connection refused
[2025-03-20T20:25:45.482+0000] {standard_task_runner.py:104} ERROR - Failed to execute job 408 for task copy_to_hdfs (Bash command failed. The command returned a non-zero exit code 1.; 719)
[2025-03-20T20:25:45.518+0000] {local_task_job_runner.py:228} INFO - Task exited with return code 1
[2025-03-20T20:25:45.554+0000] {taskinstance.py:2776} INFO - 0 downstream tasks scheduled from follow-on schedule check
