[2025-03-20T19:30:38.468+0000] {taskinstance.py:1157} INFO - Dependencies all met for dep_context=non-requeueable deps ti=<TaskInstance: transactions_pipeline.copy_to_hdfs scheduled__2025-03-20T18:40:32.992418+00:00 [queued]>
[2025-03-20T19:30:38.517+0000] {taskinstance.py:1157} INFO - Dependencies all met for dep_context=requeueable deps ti=<TaskInstance: transactions_pipeline.copy_to_hdfs scheduled__2025-03-20T18:40:32.992418+00:00 [queued]>
[2025-03-20T19:30:38.532+0000] {taskinstance.py:1359} INFO - Starting attempt 1 of 1
[2025-03-20T19:30:38.597+0000] {taskinstance.py:1380} INFO - Executing <Task(BashOperator): copy_to_hdfs> on 2025-03-20 18:40:32.992418+00:00
[2025-03-20T19:30:38.613+0000] {standard_task_runner.py:57} INFO - Started process 288 to run task
[2025-03-20T19:30:38.629+0000] {standard_task_runner.py:84} INFO - Running: ['***', 'tasks', 'run', 'transactions_pipeline', 'copy_to_hdfs', 'scheduled__2025-03-20T18:40:32.992418+00:00', '--job-id', '404', '--raw', '--subdir', 'DAGS_FOLDER/fraud_detection_pipeline.py', '--cfg-path', '/tmp/tmpbow1q25n']
[2025-03-20T19:30:38.636+0000] {standard_task_runner.py:85} INFO - Job 404: Subtask copy_to_hdfs
[2025-03-20T19:30:38.762+0000] {task_command.py:415} INFO - Running <TaskInstance: transactions_pipeline.copy_to_hdfs scheduled__2025-03-20T18:40:32.992418+00:00 [running]> on host 08ec3d25162d
[2025-03-20T19:30:39.078+0000] {taskinstance.py:1660} INFO - Exporting env vars: AIRFLOW_CTX_DAG_EMAIL='rabiizahnoune7@gmail.com' AIRFLOW_CTX_DAG_OWNER='***' AIRFLOW_CTX_DAG_ID='transactions_pipeline' AIRFLOW_CTX_TASK_ID='copy_to_hdfs' AIRFLOW_CTX_EXECUTION_DATE='2025-03-20T18:40:32.992418+00:00' AIRFLOW_CTX_TRY_NUMBER='1' AIRFLOW_CTX_DAG_RUN_ID='scheduled__2025-03-20T18:40:32.992418+00:00'
[2025-03-20T19:30:39.085+0000] {subprocess.py:63} INFO - Tmp dir root location: /tmp
[2025-03-20T19:30:39.090+0000] {subprocess.py:75} INFO - Running command: ['/bin/bash', '-c', '\n        docker exec hive hdfs dfs -mkdir -p /data/transactions/transactions_batch_20250320_144447 &&         docker exec hive hdfs dfs -put -f /data/transactions/transactions_batch_20250320_144447_nonexistent.parquet /data/transactions/transactions_batch_20250320_144447/\n        ']
[2025-03-20T19:30:39.121+0000] {subprocess.py:86} INFO - Output:
[2025-03-20T19:30:39.306+0000] {subprocess.py:93} INFO - Error response from daemon: container 7d1d06ec5b83cd6e6908cc76f4a8d49ec63667899aabcd33feb42f0032c5722e is not running
[2025-03-20T19:30:39.311+0000] {subprocess.py:97} INFO - Command exited with return code 1
[2025-03-20T19:30:39.343+0000] {taskinstance.py:1935} ERROR - Task failed with exception
Traceback (most recent call last):
  File "/home/airflow/.local/lib/python3.8/site-packages/airflow/operators/bash.py", line 210, in execute
    raise AirflowException(
airflow.exceptions.AirflowException: Bash command failed. The command returned a non-zero exit code 1.
[2025-03-20T19:30:39.354+0000] {taskinstance.py:1398} INFO - Marking task as FAILED. dag_id=transactions_pipeline, task_id=copy_to_hdfs, execution_date=20250320T184032, start_date=20250320T193038, end_date=20250320T193039
[2025-03-20T19:30:39.418+0000] {logging_mixin.py:151} WARNING - /home/***/.local/lib/python3.8/site-packages/***/utils/email.py:154 RemovedInAirflow3Warning: Fetching SMTP credentials from configuration variables will be deprecated in a future release. Please set credentials using a connection instead.
[2025-03-20T19:30:39.420+0000] {configuration.py:1063} WARNING - section/key [smtp/smtp_user] not found in config
[2025-03-20T19:30:39.421+0000] {email.py:270} INFO - Email alerting: attempt 1
[2025-03-20T19:30:39.436+0000] {configuration.py:1063} WARNING - section/key [smtp/smtp_user] not found in config
[2025-03-20T19:30:39.437+0000] {email.py:270} INFO - Email alerting: attempt 1
[2025-03-20T19:30:39.438+0000] {taskinstance.py:2005} ERROR - Failed to send email to: rabiizahnoune7@gmail.com
Traceback (most recent call last):
  File "/home/airflow/.local/lib/python3.8/site-packages/airflow/models/taskinstance.py", line 1516, in _run_raw_task
    self._execute_task_with_callbacks(context, test_mode, session=session)
  File "/home/airflow/.local/lib/python3.8/site-packages/airflow/models/taskinstance.py", line 1679, in _execute_task_with_callbacks
    result = self._execute_task(context, task_orig)
  File "/home/airflow/.local/lib/python3.8/site-packages/airflow/models/taskinstance.py", line 1742, in _execute_task
    result = execute_callable(context=context, **execute_callable_kwargs)
  File "/home/airflow/.local/lib/python3.8/site-packages/airflow/operators/bash.py", line 210, in execute
    raise AirflowException(
airflow.exceptions.AirflowException: Bash command failed. The command returned a non-zero exit code 1.

During handling of the above exception, another exception occurred:

Traceback (most recent call last):
  File "/home/airflow/.local/lib/python3.8/site-packages/airflow/models/taskinstance.py", line 2418, in email_alert
    send_email(task.email, subject, html_content)
  File "/home/airflow/.local/lib/python3.8/site-packages/airflow/utils/email.py", line 80, in send_email
    return backend(
  File "/home/airflow/.local/lib/python3.8/site-packages/airflow/utils/email.py", line 154, in send_email_smtp
    send_mime_email(e_from=mail_from, e_to=recipients, mime_msg=msg, conn_id=conn_id, dryrun=dryrun)
  File "/home/airflow/.local/lib/python3.8/site-packages/airflow/utils/email.py", line 272, in send_mime_email
    smtp_conn = _get_smtp_connection(smtp_host, smtp_port, smtp_timeout, smtp_ssl)
  File "/home/airflow/.local/lib/python3.8/site-packages/airflow/utils/email.py", line 317, in _get_smtp_connection
    return smtplib.SMTP(host=host, port=port, timeout=timeout)
  File "/usr/local/lib/python3.8/smtplib.py", line 255, in __init__
    (code, msg) = self.connect(host, port)
  File "/usr/local/lib/python3.8/smtplib.py", line 339, in connect
    self.sock = self._get_socket(host, port, self.timeout)
  File "/usr/local/lib/python3.8/smtplib.py", line 310, in _get_socket
    return socket.create_connection((host, port), timeout,
  File "/usr/local/lib/python3.8/socket.py", line 808, in create_connection
    raise err
  File "/usr/local/lib/python3.8/socket.py", line 796, in create_connection
    sock.connect(sa)
ConnectionRefusedError: [Errno 111] Connection refused

During handling of the above exception, another exception occurred:

Traceback (most recent call last):
  File "/home/airflow/.local/lib/python3.8/site-packages/airflow/models/taskinstance.py", line 2003, in handle_failure
    self.email_alert(error, task)
  File "/home/airflow/.local/lib/python3.8/site-packages/airflow/models/taskinstance.py", line 2420, in email_alert
    send_email(task.email, subject, html_content_err)
  File "/home/airflow/.local/lib/python3.8/site-packages/airflow/utils/email.py", line 80, in send_email
    return backend(
  File "/home/airflow/.local/lib/python3.8/site-packages/airflow/utils/email.py", line 154, in send_email_smtp
    send_mime_email(e_from=mail_from, e_to=recipients, mime_msg=msg, conn_id=conn_id, dryrun=dryrun)
  File "/home/airflow/.local/lib/python3.8/site-packages/airflow/utils/email.py", line 272, in send_mime_email
    smtp_conn = _get_smtp_connection(smtp_host, smtp_port, smtp_timeout, smtp_ssl)
  File "/home/airflow/.local/lib/python3.8/site-packages/airflow/utils/email.py", line 317, in _get_smtp_connection
    return smtplib.SMTP(host=host, port=port, timeout=timeout)
  File "/usr/local/lib/python3.8/smtplib.py", line 255, in __init__
    (code, msg) = self.connect(host, port)
  File "/usr/local/lib/python3.8/smtplib.py", line 339, in connect
    self.sock = self._get_socket(host, port, self.timeout)
  File "/usr/local/lib/python3.8/smtplib.py", line 310, in _get_socket
    return socket.create_connection((host, port), timeout,
  File "/usr/local/lib/python3.8/socket.py", line 808, in create_connection
    raise err
  File "/usr/local/lib/python3.8/socket.py", line 796, in create_connection
    sock.connect(sa)
ConnectionRefusedError: [Errno 111] Connection refused
[2025-03-20T19:30:39.470+0000] {configuration.py:1063} WARNING - section/key [smtp/smtp_user] not found in config
[2025-03-20T19:30:39.471+0000] {email.py:270} INFO - Email alerting: attempt 1
[2025-03-20T19:30:39.476+0000] {taskinstance.py:1703} ERROR - Error when executing on_failure_callback callback
Traceback (most recent call last):
  File "/home/airflow/.local/lib/python3.8/site-packages/airflow/models/taskinstance.py", line 1516, in _run_raw_task
    self._execute_task_with_callbacks(context, test_mode, session=session)
  File "/home/airflow/.local/lib/python3.8/site-packages/airflow/models/taskinstance.py", line 1679, in _execute_task_with_callbacks
    result = self._execute_task(context, task_orig)
  File "/home/airflow/.local/lib/python3.8/site-packages/airflow/models/taskinstance.py", line 1742, in _execute_task
    result = execute_callable(context=context, **execute_callable_kwargs)
  File "/home/airflow/.local/lib/python3.8/site-packages/airflow/operators/bash.py", line 210, in execute
    raise AirflowException(
airflow.exceptions.AirflowException: Bash command failed. The command returned a non-zero exit code 1.

During handling of the above exception, another exception occurred:

Traceback (most recent call last):
  File "/home/airflow/.local/lib/python3.8/site-packages/airflow/models/taskinstance.py", line 1700, in _run_finished_callback
    callback(context)
  File "/opt/airflow/dags/fraud_detection_pipeline.py", line 27, in on_failure_callback
    send_email(
  File "/home/airflow/.local/lib/python3.8/site-packages/airflow/utils/email.py", line 80, in send_email
    return backend(
  File "/home/airflow/.local/lib/python3.8/site-packages/airflow/utils/email.py", line 154, in send_email_smtp
    send_mime_email(e_from=mail_from, e_to=recipients, mime_msg=msg, conn_id=conn_id, dryrun=dryrun)
  File "/home/airflow/.local/lib/python3.8/site-packages/airflow/utils/email.py", line 272, in send_mime_email
    smtp_conn = _get_smtp_connection(smtp_host, smtp_port, smtp_timeout, smtp_ssl)
  File "/home/airflow/.local/lib/python3.8/site-packages/airflow/utils/email.py", line 317, in _get_smtp_connection
    return smtplib.SMTP(host=host, port=port, timeout=timeout)
  File "/usr/local/lib/python3.8/smtplib.py", line 255, in __init__
    (code, msg) = self.connect(host, port)
  File "/usr/local/lib/python3.8/smtplib.py", line 339, in connect
    self.sock = self._get_socket(host, port, self.timeout)
  File "/usr/local/lib/python3.8/smtplib.py", line 310, in _get_socket
    return socket.create_connection((host, port), timeout,
  File "/usr/local/lib/python3.8/socket.py", line 808, in create_connection
    raise err
  File "/usr/local/lib/python3.8/socket.py", line 796, in create_connection
    sock.connect(sa)
ConnectionRefusedError: [Errno 111] Connection refused
[2025-03-20T19:30:39.520+0000] {standard_task_runner.py:104} ERROR - Failed to execute job 404 for task copy_to_hdfs (Bash command failed. The command returned a non-zero exit code 1.; 288)
[2025-03-20T19:30:39.563+0000] {local_task_job_runner.py:228} INFO - Task exited with return code 1
[2025-03-20T19:30:39.648+0000] {taskinstance.py:2776} INFO - 0 downstream tasks scheduled from follow-on schedule check
