[2025-03-21T20:15:06.808+0000] {taskinstance.py:1157} INFO - Dependencies all met for dep_context=non-requeueable deps ti=<TaskInstance: external_customer_pipeline.store_customer_data_to_hdfs_and_hive manual__2025-03-21T20:14:44.778817+00:00 [queued]>
[2025-03-21T20:15:06.829+0000] {taskinstance.py:1157} INFO - Dependencies all met for dep_context=requeueable deps ti=<TaskInstance: external_customer_pipeline.store_customer_data_to_hdfs_and_hive manual__2025-03-21T20:14:44.778817+00:00 [queued]>
[2025-03-21T20:15:06.832+0000] {taskinstance.py:1359} INFO - Starting attempt 1 of 2
[2025-03-21T20:15:06.858+0000] {taskinstance.py:1380} INFO - Executing <Task(PythonOperator): store_customer_data_to_hdfs_and_hive> on 2025-03-21 20:14:44.778817+00:00
[2025-03-21T20:15:06.870+0000] {standard_task_runner.py:57} INFO - Started process 1225 to run task
[2025-03-21T20:15:06.874+0000] {standard_task_runner.py:84} INFO - Running: ['***', 'tasks', 'run', 'external_customer_pipeline', 'store_customer_data_to_hdfs_and_hive', 'manual__2025-03-21T20:14:44.778817+00:00', '--job-id', '884', '--raw', '--subdir', 'DAGS_FOLDER/pipeline_batch.py', '--cfg-path', '/tmp/tmp38fu8tu6']
[2025-03-21T20:15:06.878+0000] {standard_task_runner.py:85} INFO - Job 884: Subtask store_customer_data_to_hdfs_and_hive
[2025-03-21T20:15:06.958+0000] {task_command.py:415} INFO - Running <TaskInstance: external_customer_pipeline.store_customer_data_to_hdfs_and_hive manual__2025-03-21T20:14:44.778817+00:00 [running]> on host 4f421949e8a6
[2025-03-21T20:15:07.072+0000] {taskinstance.py:1660} INFO - Exporting env vars: AIRFLOW_CTX_DAG_OWNER='***' AIRFLOW_CTX_DAG_ID='external_customer_pipeline' AIRFLOW_CTX_TASK_ID='store_customer_data_to_hdfs_and_hive' AIRFLOW_CTX_EXECUTION_DATE='2025-03-21T20:14:44.778817+00:00' AIRFLOW_CTX_TRY_NUMBER='1' AIRFLOW_CTX_DAG_RUN_ID='manual__2025-03-21T20:14:44.778817+00:00'
[2025-03-21T20:15:09.889+0000] {pipeline_batch.py:46} INFO - Discord message sent successfully
[2025-03-21T20:15:09.892+0000] {taskinstance.py:1935} ERROR - Task failed with exception
Traceback (most recent call last):
  File "/home/airflow/.local/lib/python3.8/site-packages/airflow/operators/python.py", line 192, in execute
    return_value = self.execute_callable()
  File "/home/airflow/.local/lib/python3.8/site-packages/airflow/operators/python.py", line 209, in execute_callable
    return self.python_callable(*self.op_args, **self.op_kwargs)
  File "/opt/airflow/dags/pipeline_batch.py", line 207, in store_customer_data_to_hdfs_and_hive
    subprocess.run(
  File "/usr/local/lib/python3.8/subprocess.py", line 516, in run
    raise CalledProcessError(retcode, process.args,
subprocess.CalledProcessError: Command '['docker', 'exec', 'hive', 'hdfs', 'dfs', '-put', '-f', '/tmp/tmpbo2mzj6s', '/data/customer/customer_20250321_201444.json']' returned non-zero exit status 1.
[2025-03-21T20:15:09.915+0000] {taskinstance.py:1398} INFO - Marking task as UP_FOR_RETRY. dag_id=external_customer_pipeline, task_id=store_customer_data_to_hdfs_and_hive, execution_date=20250321T201444, start_date=20250321T201506, end_date=20250321T201509
[2025-03-21T20:15:09.936+0000] {standard_task_runner.py:104} ERROR - Failed to execute job 884 for task store_customer_data_to_hdfs_and_hive (Command '['docker', 'exec', 'hive', 'hdfs', 'dfs', '-put', '-f', '/tmp/tmpbo2mzj6s', '/data/customer/customer_20250321_201444.json']' returned non-zero exit status 1.; 1225)
[2025-03-21T20:15:09.967+0000] {local_task_job_runner.py:228} INFO - Task exited with return code 1
[2025-03-21T20:15:09.988+0000] {taskinstance.py:2776} INFO - 0 downstream tasks scheduled from follow-on schedule check
