[2025-03-21T20:24:10.856+0000] {taskinstance.py:1157} INFO - Dependencies all met for dep_context=non-requeueable deps ti=<TaskInstance: external_customer_pipeline.store_external_data_to_hdfs_and_hive manual__2025-03-21T20:19:39.307019+00:00 [queued]>
[2025-03-21T20:24:10.897+0000] {taskinstance.py:1157} INFO - Dependencies all met for dep_context=requeueable deps ti=<TaskInstance: external_customer_pipeline.store_external_data_to_hdfs_and_hive manual__2025-03-21T20:19:39.307019+00:00 [queued]>
[2025-03-21T20:24:10.899+0000] {taskinstance.py:1359} INFO - Starting attempt 3 of 3
[2025-03-21T20:24:10.933+0000] {taskinstance.py:1380} INFO - Executing <Task(PythonOperator): store_external_data_to_hdfs_and_hive> on 2025-03-21 20:19:39.307019+00:00
[2025-03-21T20:24:10.946+0000] {standard_task_runner.py:57} INFO - Started process 1857 to run task
[2025-03-21T20:24:10.952+0000] {standard_task_runner.py:84} INFO - Running: ['***', 'tasks', 'run', 'external_customer_pipeline', 'store_external_data_to_hdfs_and_hive', 'manual__2025-03-21T20:19:39.307019+00:00', '--job-id', '898', '--raw', '--subdir', 'DAGS_FOLDER/pipeline_batch.py', '--cfg-path', '/tmp/tmpy6i4svu6']
[2025-03-21T20:24:10.962+0000] {standard_task_runner.py:85} INFO - Job 898: Subtask store_external_data_to_hdfs_and_hive
[2025-03-21T20:24:11.088+0000] {task_command.py:415} INFO - Running <TaskInstance: external_customer_pipeline.store_external_data_to_hdfs_and_hive manual__2025-03-21T20:19:39.307019+00:00 [running]> on host 4f421949e8a6
[2025-03-21T20:24:11.325+0000] {taskinstance.py:1660} INFO - Exporting env vars: AIRFLOW_CTX_DAG_OWNER='***' AIRFLOW_CTX_DAG_ID='external_customer_pipeline' AIRFLOW_CTX_TASK_ID='store_external_data_to_hdfs_and_hive' AIRFLOW_CTX_EXECUTION_DATE='2025-03-21T20:19:39.307019+00:00' AIRFLOW_CTX_TRY_NUMBER='3' AIRFLOW_CTX_DAG_RUN_ID='manual__2025-03-21T20:19:39.307019+00:00'
[2025-03-21T20:24:15.300+0000] {pipeline_batch.py:169} INFO - HDFS put command output: 
[2025-03-21T20:24:26.070+0000] {pipeline_batch.py:44} INFO - Discord message sent successfully
[2025-03-21T20:24:26.075+0000] {taskinstance.py:1935} ERROR - Task failed with exception
Traceback (most recent call last):
  File "/home/airflow/.local/lib/python3.8/site-packages/airflow/operators/python.py", line 192, in execute
    return_value = self.execute_callable()
  File "/home/airflow/.local/lib/python3.8/site-packages/airflow/operators/python.py", line 209, in execute_callable
    return self.python_callable(*self.op_args, **self.op_kwargs)
  File "/opt/airflow/dags/pipeline_batch.py", line 188, in store_external_data_to_hdfs_and_hive
    subprocess.run(create_table_cmd, shell=True, check=True)
  File "/usr/local/lib/python3.8/subprocess.py", line 516, in run
    raise CalledProcessError(retcode, process.args,
subprocess.CalledProcessError: Command '
            docker exec hive beeline -u "jdbc:hive2://localhost:10000" --hiveconf hive.exec.dynamic.partition.mode=nonstrict -e "
            CREATE EXTERNAL TABLE IF NOT EXISTS external_data (
                blacklist_info ARRAY<STRING>,
                credit_scores MAP<STRING, INT>,
                fraud_reports MAP<STRING, INT>
            )
            PARTITIONED BY (batch_id STRING)
            STORED AS JSONFILE
            LOCATION '/data/external_data';
            ALTER TABLE external_data ADD IF NOT EXISTS PARTITION (batch_id='20250321_201939') LOCATION '/data/external_data/external_data_20250321_201939.json';"
            ' returned non-zero exit status 1.
[2025-03-21T20:24:26.101+0000] {taskinstance.py:1398} INFO - Marking task as FAILED. dag_id=external_customer_pipeline, task_id=store_external_data_to_hdfs_and_hive, execution_date=20250321T201939, start_date=20250321T202410, end_date=20250321T202426
[2025-03-21T20:24:26.113+0000] {logging_mixin.py:151} WARNING - /home/***/.local/lib/python3.8/site-packages/***/utils/context.py:206 AirflowContextDeprecationWarning: Accessing 'execution_date' from the template is deprecated and will be removed in a future version. Please use 'data_interval_start' or 'logical_date' instead.
[2025-03-21T20:24:26.532+0000] {pipeline_batch.py:44} INFO - Discord message sent successfully
[2025-03-21T20:24:26.557+0000] {standard_task_runner.py:104} ERROR - Failed to execute job 898 for task store_external_data_to_hdfs_and_hive (Command '
            docker exec hive beeline -u "jdbc:hive2://localhost:10000" --hiveconf hive.exec.dynamic.partition.mode=nonstrict -e "
            CREATE EXTERNAL TABLE IF NOT EXISTS external_data (
                blacklist_info ARRAY<STRING>,
                credit_scores MAP<STRING, INT>,
                fraud_reports MAP<STRING, INT>
            )
            PARTITIONED BY (batch_id STRING)
            STORED AS JSONFILE
            LOCATION '/data/external_data';
            ALTER TABLE external_data ADD IF NOT EXISTS PARTITION (batch_id='20250321_201939') LOCATION '/data/external_data/external_data_20250321_201939.json';"
            ' returned non-zero exit status 1.; 1857)
[2025-03-21T20:24:26.573+0000] {local_task_job_runner.py:228} INFO - Task exited with return code 1
[2025-03-21T20:24:26.602+0000] {taskinstance.py:2776} INFO - 0 downstream tasks scheduled from follow-on schedule check
