[2025-03-21T20:20:01.776+0000] {taskinstance.py:1157} INFO - Dependencies all met for dep_context=non-requeueable deps ti=<TaskInstance: external_customer_pipeline.store_external_data_to_hdfs_and_hive manual__2025-03-21T20:19:39.307019+00:00 [queued]>
[2025-03-21T20:20:01.789+0000] {taskinstance.py:1157} INFO - Dependencies all met for dep_context=requeueable deps ti=<TaskInstance: external_customer_pipeline.store_external_data_to_hdfs_and_hive manual__2025-03-21T20:19:39.307019+00:00 [queued]>
[2025-03-21T20:20:01.792+0000] {taskinstance.py:1359} INFO - Starting attempt 1 of 3
[2025-03-21T20:20:01.813+0000] {taskinstance.py:1380} INFO - Executing <Task(PythonOperator): store_external_data_to_hdfs_and_hive> on 2025-03-21 20:19:39.307019+00:00
[2025-03-21T20:20:01.820+0000] {standard_task_runner.py:57} INFO - Started process 1629 to run task
[2025-03-21T20:20:01.826+0000] {standard_task_runner.py:84} INFO - Running: ['***', 'tasks', 'run', 'external_customer_pipeline', 'store_external_data_to_hdfs_and_hive', 'manual__2025-03-21T20:19:39.307019+00:00', '--job-id', '894', '--raw', '--subdir', 'DAGS_FOLDER/pipeline_batch.py', '--cfg-path', '/tmp/tmpkux72zli']
[2025-03-21T20:20:01.830+0000] {standard_task_runner.py:85} INFO - Job 894: Subtask store_external_data_to_hdfs_and_hive
[2025-03-21T20:20:01.899+0000] {task_command.py:415} INFO - Running <TaskInstance: external_customer_pipeline.store_external_data_to_hdfs_and_hive manual__2025-03-21T20:19:39.307019+00:00 [running]> on host 4f421949e8a6
[2025-03-21T20:20:02.011+0000] {taskinstance.py:1660} INFO - Exporting env vars: AIRFLOW_CTX_DAG_OWNER='***' AIRFLOW_CTX_DAG_ID='external_customer_pipeline' AIRFLOW_CTX_TASK_ID='store_external_data_to_hdfs_and_hive' AIRFLOW_CTX_EXECUTION_DATE='2025-03-21T20:19:39.307019+00:00' AIRFLOW_CTX_TRY_NUMBER='1' AIRFLOW_CTX_DAG_RUN_ID='manual__2025-03-21T20:19:39.307019+00:00'
[2025-03-21T20:20:04.883+0000] {pipeline_batch.py:177} ERROR - HDFS put command failed: put: `/tmp/tmpaozviyyf': No such file or directory

[2025-03-21T20:20:05.277+0000] {pipeline_batch.py:47} INFO - Discord message sent successfully
[2025-03-21T20:20:05.295+0000] {taskinstance.py:1935} ERROR - Task failed with exception
Traceback (most recent call last):
  File "/opt/airflow/dags/pipeline_batch.py", line 168, in store_external_data_to_hdfs_and_hive
    result = subprocess.run(
  File "/usr/local/lib/python3.8/subprocess.py", line 516, in run
    raise CalledProcessError(retcode, process.args,
subprocess.CalledProcessError: Command '['docker', 'exec', 'hive', 'hdfs', 'dfs', '-put', '-f', '/tmp/tmpaozviyyf', '/data/external_data/external_data_20250321_201939.json']' returned non-zero exit status 1.

During handling of the above exception, another exception occurred:

Traceback (most recent call last):
  File "/home/airflow/.local/lib/python3.8/site-packages/airflow/operators/python.py", line 192, in execute
    return_value = self.execute_callable()
  File "/home/airflow/.local/lib/python3.8/site-packages/airflow/operators/python.py", line 209, in execute_callable
    return self.python_callable(*self.op_args, **self.op_kwargs)
  File "/opt/airflow/dags/pipeline_batch.py", line 178, in store_external_data_to_hdfs_and_hive
    raise RuntimeError(error_message)
RuntimeError: HDFS put command failed: put: `/tmp/tmpaozviyyf': No such file or directory

[2025-03-21T20:20:05.321+0000] {taskinstance.py:1398} INFO - Marking task as UP_FOR_RETRY. dag_id=external_customer_pipeline, task_id=store_external_data_to_hdfs_and_hive, execution_date=20250321T201939, start_date=20250321T202001, end_date=20250321T202005
[2025-03-21T20:20:05.347+0000] {standard_task_runner.py:104} ERROR - Failed to execute job 894 for task store_external_data_to_hdfs_and_hive (HDFS put command failed: put: `/tmp/tmpaozviyyf': No such file or directory
; 1629)
[2025-03-21T20:20:05.381+0000] {local_task_job_runner.py:228} INFO - Task exited with return code 1
[2025-03-21T20:20:05.422+0000] {taskinstance.py:2776} INFO - 0 downstream tasks scheduled from follow-on schedule check
