[2025-03-21T12:33:07.766+0000] {taskinstance.py:1157} INFO - Dependencies all met for dep_context=non-requeueable deps ti=<TaskInstance: transactions_pipeline.generate_processing_tasks scheduled__2025-03-21T12:28:01.937663+00:00 [queued]>
[2025-03-21T12:33:07.790+0000] {taskinstance.py:1157} INFO - Dependencies all met for dep_context=requeueable deps ti=<TaskInstance: transactions_pipeline.generate_processing_tasks scheduled__2025-03-21T12:28:01.937663+00:00 [queued]>
[2025-03-21T12:33:07.791+0000] {taskinstance.py:1359} INFO - Starting attempt 1 of 2
[2025-03-21T12:33:07.828+0000] {taskinstance.py:1380} INFO - Executing <Task(PythonOperator): generate_processing_tasks> on 2025-03-21 12:28:01.937663+00:00
[2025-03-21T12:33:07.842+0000] {standard_task_runner.py:84} INFO - Running: ['***', 'tasks', 'run', 'transactions_pipeline', 'generate_processing_tasks', 'scheduled__2025-03-21T12:28:01.937663+00:00', '--job-id', '517', '--raw', '--subdir', 'DAGS_FOLDER/fraud_detection_pipeline.py', '--cfg-path', '/tmp/tmp7ggpvp3x']
[2025-03-21T12:33:07.842+0000] {standard_task_runner.py:57} INFO - Started process 5338 to run task
[2025-03-21T12:33:07.847+0000] {standard_task_runner.py:85} INFO - Job 517: Subtask generate_processing_tasks
[2025-03-21T12:33:08.099+0000] {task_command.py:415} INFO - Running <TaskInstance: transactions_pipeline.generate_processing_tasks scheduled__2025-03-21T12:28:01.937663+00:00 [running]> on host 6688e233cb20
[2025-03-21T12:33:08.456+0000] {taskinstance.py:1660} INFO - Exporting env vars: AIRFLOW_CTX_DAG_EMAIL='rabiizahnoune7@gmail.com' AIRFLOW_CTX_DAG_OWNER='***' AIRFLOW_CTX_DAG_ID='transactions_pipeline' AIRFLOW_CTX_TASK_ID='generate_processing_tasks' AIRFLOW_CTX_EXECUTION_DATE='2025-03-21T12:28:01.937663+00:00' AIRFLOW_CTX_TRY_NUMBER='1' AIRFLOW_CTX_DAG_RUN_ID='scheduled__2025-03-21T12:28:01.937663+00:00'
[2025-03-21T12:33:08.524+0000] {taskinstance.py:1935} ERROR - Task failed with exception
Traceback (most recent call last):
  File "/home/airflow/.local/lib/python3.8/site-packages/airflow/operators/python.py", line 192, in execute
    return_value = self.execute_callable()
  File "/home/airflow/.local/lib/python3.8/site-packages/airflow/operators/python.py", line 209, in execute_callable
    return self.python_callable(*self.op_args, **self.op_kwargs)
  File "/opt/airflow/dags/fraud_detection_pipeline.py", line 206, in generate_processing_tasks
    process_file(file_path)
  File "/opt/airflow/dags/fraud_detection_pipeline.py", line 193, in process_file
    copy_to_hdfs >> create_table >> create_fraud_table >> detect_fraud >> move_processed_file
  File "/home/airflow/.local/lib/python3.8/site-packages/airflow/models/taskmixin.py", line 103, in __rshift__
    self.set_downstream(other)
  File "/home/airflow/.local/lib/python3.8/site-packages/airflow/models/taskmixin.py", line 261, in set_downstream
    self._set_relatives(task_or_task_list, upstream=False, edge_modifier=edge_modifier)
  File "/home/airflow/.local/lib/python3.8/site-packages/airflow/models/taskmixin.py", line 231, in _set_relatives
    raise AirflowException(
airflow.exceptions.AirflowException: Tried to create relationships between tasks that don't have DAGs yet. Set the DAG for at least one task and try again: [<Task(BashOperator): copy_to_hdfs_batch_20250320_135205>, <Task(BashOperator): create_hive_table_batch_20250320_135205>]
[2025-03-21T12:33:08.550+0000] {taskinstance.py:1398} INFO - Marking task as UP_FOR_RETRY. dag_id=transactions_pipeline, task_id=generate_processing_tasks, execution_date=20250321T122801, start_date=20250321T123307, end_date=20250321T123308
[2025-03-21T12:33:08.626+0000] {logging_mixin.py:151} WARNING - /home/***/.local/lib/python3.8/site-packages/***/utils/email.py:154 RemovedInAirflow3Warning: Fetching SMTP credentials from configuration variables will be deprecated in a future release. Please set credentials using a connection instead.
[2025-03-21T12:33:08.627+0000] {configuration.py:1063} WARNING - section/key [smtp/smtp_user] not found in config
[2025-03-21T12:33:08.627+0000] {email.py:270} INFO - Email alerting: attempt 1
[2025-03-21T12:33:08.671+0000] {configuration.py:1063} WARNING - section/key [smtp/smtp_user] not found in config
[2025-03-21T12:33:08.672+0000] {email.py:270} INFO - Email alerting: attempt 1
[2025-03-21T12:33:08.673+0000] {taskinstance.py:2005} ERROR - Failed to send email to: rabiizahnoune7@gmail.com
Traceback (most recent call last):
  File "/home/airflow/.local/lib/python3.8/site-packages/airflow/models/taskinstance.py", line 1516, in _run_raw_task
    self._execute_task_with_callbacks(context, test_mode, session=session)
  File "/home/airflow/.local/lib/python3.8/site-packages/airflow/models/taskinstance.py", line 1679, in _execute_task_with_callbacks
    result = self._execute_task(context, task_orig)
  File "/home/airflow/.local/lib/python3.8/site-packages/airflow/models/taskinstance.py", line 1742, in _execute_task
    result = execute_callable(context=context, **execute_callable_kwargs)
  File "/home/airflow/.local/lib/python3.8/site-packages/airflow/operators/python.py", line 192, in execute
    return_value = self.execute_callable()
  File "/home/airflow/.local/lib/python3.8/site-packages/airflow/operators/python.py", line 209, in execute_callable
    return self.python_callable(*self.op_args, **self.op_kwargs)
  File "/opt/airflow/dags/fraud_detection_pipeline.py", line 206, in generate_processing_tasks
    process_file(file_path)
  File "/opt/airflow/dags/fraud_detection_pipeline.py", line 193, in process_file
    copy_to_hdfs >> create_table >> create_fraud_table >> detect_fraud >> move_processed_file
  File "/home/airflow/.local/lib/python3.8/site-packages/airflow/models/taskmixin.py", line 103, in __rshift__
    self.set_downstream(other)
  File "/home/airflow/.local/lib/python3.8/site-packages/airflow/models/taskmixin.py", line 261, in set_downstream
    self._set_relatives(task_or_task_list, upstream=False, edge_modifier=edge_modifier)
  File "/home/airflow/.local/lib/python3.8/site-packages/airflow/models/taskmixin.py", line 231, in _set_relatives
    raise AirflowException(
airflow.exceptions.AirflowException: Tried to create relationships between tasks that don't have DAGs yet. Set the DAG for at least one task and try again: [<Task(BashOperator): copy_to_hdfs_batch_20250320_135205>, <Task(BashOperator): create_hive_table_batch_20250320_135205>]

During handling of the above exception, another exception occurred:

Traceback (most recent call last):
  File "/home/airflow/.local/lib/python3.8/site-packages/airflow/models/taskinstance.py", line 2418, in email_alert
    send_email(task.email, subject, html_content)
  File "/home/airflow/.local/lib/python3.8/site-packages/airflow/utils/email.py", line 80, in send_email
    return backend(
  File "/home/airflow/.local/lib/python3.8/site-packages/airflow/utils/email.py", line 154, in send_email_smtp
    send_mime_email(e_from=mail_from, e_to=recipients, mime_msg=msg, conn_id=conn_id, dryrun=dryrun)
  File "/home/airflow/.local/lib/python3.8/site-packages/airflow/utils/email.py", line 272, in send_mime_email
    smtp_conn = _get_smtp_connection(smtp_host, smtp_port, smtp_timeout, smtp_ssl)
  File "/home/airflow/.local/lib/python3.8/site-packages/airflow/utils/email.py", line 317, in _get_smtp_connection
    return smtplib.SMTP(host=host, port=port, timeout=timeout)
  File "/usr/local/lib/python3.8/smtplib.py", line 255, in __init__
    (code, msg) = self.connect(host, port)
  File "/usr/local/lib/python3.8/smtplib.py", line 339, in connect
    self.sock = self._get_socket(host, port, self.timeout)
  File "/usr/local/lib/python3.8/smtplib.py", line 310, in _get_socket
    return socket.create_connection((host, port), timeout,
  File "/usr/local/lib/python3.8/socket.py", line 808, in create_connection
    raise err
  File "/usr/local/lib/python3.8/socket.py", line 796, in create_connection
    sock.connect(sa)
ConnectionRefusedError: [Errno 111] Connection refused

During handling of the above exception, another exception occurred:

Traceback (most recent call last):
  File "/home/airflow/.local/lib/python3.8/site-packages/airflow/models/taskinstance.py", line 2003, in handle_failure
    self.email_alert(error, task)
  File "/home/airflow/.local/lib/python3.8/site-packages/airflow/models/taskinstance.py", line 2420, in email_alert
    send_email(task.email, subject, html_content_err)
  File "/home/airflow/.local/lib/python3.8/site-packages/airflow/utils/email.py", line 80, in send_email
    return backend(
  File "/home/airflow/.local/lib/python3.8/site-packages/airflow/utils/email.py", line 154, in send_email_smtp
    send_mime_email(e_from=mail_from, e_to=recipients, mime_msg=msg, conn_id=conn_id, dryrun=dryrun)
  File "/home/airflow/.local/lib/python3.8/site-packages/airflow/utils/email.py", line 272, in send_mime_email
    smtp_conn = _get_smtp_connection(smtp_host, smtp_port, smtp_timeout, smtp_ssl)
  File "/home/airflow/.local/lib/python3.8/site-packages/airflow/utils/email.py", line 317, in _get_smtp_connection
    return smtplib.SMTP(host=host, port=port, timeout=timeout)
  File "/usr/local/lib/python3.8/smtplib.py", line 255, in __init__
    (code, msg) = self.connect(host, port)
  File "/usr/local/lib/python3.8/smtplib.py", line 339, in connect
    self.sock = self._get_socket(host, port, self.timeout)
  File "/usr/local/lib/python3.8/smtplib.py", line 310, in _get_socket
    return socket.create_connection((host, port), timeout,
  File "/usr/local/lib/python3.8/socket.py", line 808, in create_connection
    raise err
  File "/usr/local/lib/python3.8/socket.py", line 796, in create_connection
    sock.connect(sa)
ConnectionRefusedError: [Errno 111] Connection refused
[2025-03-21T12:33:08.726+0000] {standard_task_runner.py:104} ERROR - Failed to execute job 517 for task generate_processing_tasks (Tried to create relationships between tasks that don't have DAGs yet. Set the DAG for at least one task and try again: [<Task(BashOperator): copy_to_hdfs_batch_20250320_135205>, <Task(BashOperator): create_hive_table_batch_20250320_135205>]; 5338)
[2025-03-21T12:33:08.756+0000] {local_task_job_runner.py:228} INFO - Task exited with return code 1
[2025-03-21T12:33:08.794+0000] {taskinstance.py:2776} INFO - 0 downstream tasks scheduled from follow-on schedule check
