[2025-03-21T20:06:53.618+0000] {taskinstance.py:1157} INFO - Dependencies all met for dep_context=non-requeueable deps ti=<TaskInstance: external_customer_pipeline.fetch_and_store_customer_data manual__2025-03-21T20:01:25.926461+00:00 [queued]>
[2025-03-21T20:06:53.633+0000] {taskinstance.py:1157} INFO - Dependencies all met for dep_context=requeueable deps ti=<TaskInstance: external_customer_pipeline.fetch_and_store_customer_data manual__2025-03-21T20:01:25.926461+00:00 [queued]>
[2025-03-21T20:06:53.634+0000] {taskinstance.py:1359} INFO - Starting attempt 2 of 2
[2025-03-21T20:06:53.660+0000] {taskinstance.py:1380} INFO - Executing <Task(PythonOperator): fetch_and_store_customer_data> on 2025-03-21 20:01:25.926461+00:00
[2025-03-21T20:06:53.695+0000] {standard_task_runner.py:57} INFO - Started process 676 to run task
[2025-03-21T20:06:53.700+0000] {standard_task_runner.py:84} INFO - Running: ['***', 'tasks', 'run', 'external_customer_pipeline', 'fetch_and_store_customer_data', 'manual__2025-03-21T20:01:25.926461+00:00', '--job-id', '868', '--raw', '--subdir', 'DAGS_FOLDER/pipeline_batch.py', '--cfg-path', '/tmp/tmphul8jgnu']
[2025-03-21T20:06:53.706+0000] {standard_task_runner.py:85} INFO - Job 868: Subtask fetch_and_store_customer_data
[2025-03-21T20:06:53.789+0000] {task_command.py:415} INFO - Running <TaskInstance: external_customer_pipeline.fetch_and_store_customer_data manual__2025-03-21T20:01:25.926461+00:00 [running]> on host 4f421949e8a6
[2025-03-21T20:06:53.914+0000] {taskinstance.py:1660} INFO - Exporting env vars: AIRFLOW_CTX_DAG_OWNER='***' AIRFLOW_CTX_DAG_ID='external_customer_pipeline' AIRFLOW_CTX_TASK_ID='fetch_and_store_customer_data' AIRFLOW_CTX_EXECUTION_DATE='2025-03-21T20:01:25.926461+00:00' AIRFLOW_CTX_TRY_NUMBER='2' AIRFLOW_CTX_DAG_RUN_ID='manual__2025-03-21T20:01:25.926461+00:00'
[2025-03-21T20:06:53.925+0000] {logging_mixin.py:151} WARNING - /home/***/.local/lib/python3.8/site-packages/***/utils/context.py:314 AirflowContextDeprecationWarning: Accessing 'execution_date' from the template is deprecated and will be removed in a future version. Please use 'data_interval_start' or 'logical_date' instead.
[2025-03-21T20:07:00.402+0000] {pipeline_batch.py:44} INFO - Discord message sent successfully
[2025-03-21T20:07:00.408+0000] {taskinstance.py:1935} ERROR - Task failed with exception
Traceback (most recent call last):
  File "/home/airflow/.local/lib/python3.8/site-packages/airflow/operators/python.py", line 192, in execute
    return_value = self.execute_callable()
  File "/home/airflow/.local/lib/python3.8/site-packages/airflow/operators/python.py", line 209, in execute_callable
    return self.python_callable(*self.op_args, **self.op_kwargs)
  File "/opt/airflow/dags/pipeline_batch.py", line 167, in fetch_and_store_customer_data
    subprocess.run(
  File "/usr/local/lib/python3.8/subprocess.py", line 516, in run
    raise CalledProcessError(retcode, process.args,
subprocess.CalledProcessError: Command '['docker', 'exec', 'hive', 'hdfs', 'dfs', '-put', '-f', '/tmp/customer_20250321_200125.json', '/data/customer/customer_20250321_200125.json']' returned non-zero exit status 1.
[2025-03-21T20:07:00.430+0000] {taskinstance.py:1398} INFO - Marking task as FAILED. dag_id=external_customer_pipeline, task_id=fetch_and_store_customer_data, execution_date=20250321T200125, start_date=20250321T200653, end_date=20250321T200700
[2025-03-21T20:07:00.432+0000] {logging_mixin.py:151} WARNING - /home/***/.local/lib/python3.8/site-packages/***/utils/context.py:206 AirflowContextDeprecationWarning: Accessing 'execution_date' from the template is deprecated and will be removed in a future version. Please use 'data_interval_start' or 'logical_date' instead.
[2025-03-21T20:07:00.780+0000] {pipeline_batch.py:44} INFO - Discord message sent successfully
[2025-03-21T20:07:00.801+0000] {standard_task_runner.py:104} ERROR - Failed to execute job 868 for task fetch_and_store_customer_data (Command '['docker', 'exec', 'hive', 'hdfs', 'dfs', '-put', '-f', '/tmp/customer_20250321_200125.json', '/data/customer/customer_20250321_200125.json']' returned non-zero exit status 1.; 676)
[2025-03-21T20:07:00.831+0000] {local_task_job_runner.py:228} INFO - Task exited with return code 1
[2025-03-21T20:07:00.855+0000] {taskinstance.py:2776} INFO - 0 downstream tasks scheduled from follow-on schedule check
