[2025-03-20T22:01:09.894+0000] {taskinstance.py:1157} INFO - Dependencies all met for dep_context=non-requeueable deps ti=<TaskInstance: transactions_pipeline.detect_fraud scheduled__2025-03-20T21:10:32.992418+00:00 [queued]>
[2025-03-20T22:01:09.905+0000] {taskinstance.py:1157} INFO - Dependencies all met for dep_context=requeueable deps ti=<TaskInstance: transactions_pipeline.detect_fraud scheduled__2025-03-20T21:10:32.992418+00:00 [queued]>
[2025-03-20T22:01:09.906+0000] {taskinstance.py:1359} INFO - Starting attempt 1 of 2
[2025-03-20T22:01:09.922+0000] {taskinstance.py:1380} INFO - Executing <Task(BashOperator): detect_fraud> on 2025-03-20 21:10:32.992418+00:00
[2025-03-20T22:01:09.929+0000] {standard_task_runner.py:57} INFO - Started process 509 to run task
[2025-03-20T22:01:09.932+0000] {standard_task_runner.py:84} INFO - Running: ['***', 'tasks', 'run', 'transactions_pipeline', 'detect_fraud', 'scheduled__2025-03-20T21:10:32.992418+00:00', '--job-id', '421', '--raw', '--subdir', 'DAGS_FOLDER/fraud_detection_pipeline.py', '--cfg-path', '/tmp/tmp160hsjft']
[2025-03-20T22:01:09.936+0000] {standard_task_runner.py:85} INFO - Job 421: Subtask detect_fraud
[2025-03-20T22:01:09.989+0000] {task_command.py:415} INFO - Running <TaskInstance: transactions_pipeline.detect_fraud scheduled__2025-03-20T21:10:32.992418+00:00 [running]> on host 9e96247a5f22
[2025-03-20T22:01:10.094+0000] {taskinstance.py:1660} INFO - Exporting env vars: AIRFLOW_CTX_DAG_EMAIL='rabiizahnoune7@gmail.com' AIRFLOW_CTX_DAG_OWNER='***' AIRFLOW_CTX_DAG_ID='transactions_pipeline' AIRFLOW_CTX_TASK_ID='detect_fraud' AIRFLOW_CTX_EXECUTION_DATE='2025-03-20T21:10:32.992418+00:00' AIRFLOW_CTX_TRY_NUMBER='1' AIRFLOW_CTX_DAG_RUN_ID='scheduled__2025-03-20T21:10:32.992418+00:00'
[2025-03-20T22:01:10.096+0000] {subprocess.py:63} INFO - Tmp dir root location: /tmp
[2025-03-20T22:01:10.098+0000] {subprocess.py:75} INFO - Running command: ['/bin/bash', '-c', '\n        docker exec hive spark-submit --master spark://localhost:7077 /hive/scripts/detect_fraud.py "batch_20250320_144447"\n        ']
[2025-03-20T22:01:10.111+0000] {subprocess.py:86} INFO - Output:
[2025-03-20T22:01:13.857+0000] {subprocess.py:93} INFO - Traceback (most recent call last):
[2025-03-20T22:01:13.858+0000] {subprocess.py:93} INFO -   File "/hive/scripts/detect_fraud.py", line 4, in <module>
[2025-03-20T22:01:13.861+0000] {subprocess.py:93} INFO -     from dotenv import load_dotenv
[2025-03-20T22:01:13.862+0000] {subprocess.py:93} INFO - ModuleNotFoundError: No module named 'dotenv'
[2025-03-20T22:01:13.908+0000] {subprocess.py:93} INFO - 25/03/20 22:01:13 INFO ShutdownHookManager: Shutdown hook called
[2025-03-20T22:01:13.914+0000] {subprocess.py:93} INFO - 25/03/20 22:01:13 INFO ShutdownHookManager: Deleting directory /tmp/spark-6b126491-cb6a-4a0a-a7e1-edfbae07065a
[2025-03-20T22:01:13.954+0000] {subprocess.py:97} INFO - Command exited with return code 1
[2025-03-20T22:01:13.972+0000] {taskinstance.py:1935} ERROR - Task failed with exception
Traceback (most recent call last):
  File "/home/airflow/.local/lib/python3.8/site-packages/airflow/operators/bash.py", line 210, in execute
    raise AirflowException(
airflow.exceptions.AirflowException: Bash command failed. The command returned a non-zero exit code 1.
[2025-03-20T22:01:13.979+0000] {taskinstance.py:1398} INFO - Marking task as UP_FOR_RETRY. dag_id=transactions_pipeline, task_id=detect_fraud, execution_date=20250320T211032, start_date=20250320T220109, end_date=20250320T220113
[2025-03-20T22:01:14.007+0000] {logging_mixin.py:151} WARNING - /home/***/.local/lib/python3.8/site-packages/***/utils/email.py:154 RemovedInAirflow3Warning: Fetching SMTP credentials from configuration variables will be deprecated in a future release. Please set credentials using a connection instead.
[2025-03-20T22:01:14.009+0000] {configuration.py:1063} WARNING - section/key [smtp/smtp_user] not found in config
[2025-03-20T22:01:14.010+0000] {email.py:270} INFO - Email alerting: attempt 1
[2025-03-20T22:01:14.022+0000] {configuration.py:1063} WARNING - section/key [smtp/smtp_user] not found in config
[2025-03-20T22:01:14.023+0000] {email.py:270} INFO - Email alerting: attempt 1
[2025-03-20T22:01:14.025+0000] {taskinstance.py:2005} ERROR - Failed to send email to: rabiizahnoune7@gmail.com
Traceback (most recent call last):
  File "/home/airflow/.local/lib/python3.8/site-packages/airflow/models/taskinstance.py", line 1516, in _run_raw_task
    self._execute_task_with_callbacks(context, test_mode, session=session)
  File "/home/airflow/.local/lib/python3.8/site-packages/airflow/models/taskinstance.py", line 1679, in _execute_task_with_callbacks
    result = self._execute_task(context, task_orig)
  File "/home/airflow/.local/lib/python3.8/site-packages/airflow/models/taskinstance.py", line 1742, in _execute_task
    result = execute_callable(context=context, **execute_callable_kwargs)
  File "/home/airflow/.local/lib/python3.8/site-packages/airflow/operators/bash.py", line 210, in execute
    raise AirflowException(
airflow.exceptions.AirflowException: Bash command failed. The command returned a non-zero exit code 1.

During handling of the above exception, another exception occurred:

Traceback (most recent call last):
  File "/home/airflow/.local/lib/python3.8/site-packages/airflow/models/taskinstance.py", line 2418, in email_alert
    send_email(task.email, subject, html_content)
  File "/home/airflow/.local/lib/python3.8/site-packages/airflow/utils/email.py", line 80, in send_email
    return backend(
  File "/home/airflow/.local/lib/python3.8/site-packages/airflow/utils/email.py", line 154, in send_email_smtp
    send_mime_email(e_from=mail_from, e_to=recipients, mime_msg=msg, conn_id=conn_id, dryrun=dryrun)
  File "/home/airflow/.local/lib/python3.8/site-packages/airflow/utils/email.py", line 272, in send_mime_email
    smtp_conn = _get_smtp_connection(smtp_host, smtp_port, smtp_timeout, smtp_ssl)
  File "/home/airflow/.local/lib/python3.8/site-packages/airflow/utils/email.py", line 317, in _get_smtp_connection
    return smtplib.SMTP(host=host, port=port, timeout=timeout)
  File "/usr/local/lib/python3.8/smtplib.py", line 255, in __init__
    (code, msg) = self.connect(host, port)
  File "/usr/local/lib/python3.8/smtplib.py", line 339, in connect
    self.sock = self._get_socket(host, port, self.timeout)
  File "/usr/local/lib/python3.8/smtplib.py", line 310, in _get_socket
    return socket.create_connection((host, port), timeout,
  File "/usr/local/lib/python3.8/socket.py", line 808, in create_connection
    raise err
  File "/usr/local/lib/python3.8/socket.py", line 796, in create_connection
    sock.connect(sa)
ConnectionRefusedError: [Errno 111] Connection refused

During handling of the above exception, another exception occurred:

Traceback (most recent call last):
  File "/home/airflow/.local/lib/python3.8/site-packages/airflow/models/taskinstance.py", line 2003, in handle_failure
    self.email_alert(error, task)
  File "/home/airflow/.local/lib/python3.8/site-packages/airflow/models/taskinstance.py", line 2420, in email_alert
    send_email(task.email, subject, html_content_err)
  File "/home/airflow/.local/lib/python3.8/site-packages/airflow/utils/email.py", line 80, in send_email
    return backend(
  File "/home/airflow/.local/lib/python3.8/site-packages/airflow/utils/email.py", line 154, in send_email_smtp
    send_mime_email(e_from=mail_from, e_to=recipients, mime_msg=msg, conn_id=conn_id, dryrun=dryrun)
  File "/home/airflow/.local/lib/python3.8/site-packages/airflow/utils/email.py", line 272, in send_mime_email
    smtp_conn = _get_smtp_connection(smtp_host, smtp_port, smtp_timeout, smtp_ssl)
  File "/home/airflow/.local/lib/python3.8/site-packages/airflow/utils/email.py", line 317, in _get_smtp_connection
    return smtplib.SMTP(host=host, port=port, timeout=timeout)
  File "/usr/local/lib/python3.8/smtplib.py", line 255, in __init__
    (code, msg) = self.connect(host, port)
  File "/usr/local/lib/python3.8/smtplib.py", line 339, in connect
    self.sock = self._get_socket(host, port, self.timeout)
  File "/usr/local/lib/python3.8/smtplib.py", line 310, in _get_socket
    return socket.create_connection((host, port), timeout,
  File "/usr/local/lib/python3.8/socket.py", line 808, in create_connection
    raise err
  File "/usr/local/lib/python3.8/socket.py", line 796, in create_connection
    sock.connect(sa)
ConnectionRefusedError: [Errno 111] Connection refused
[2025-03-20T22:01:14.053+0000] {standard_task_runner.py:104} ERROR - Failed to execute job 421 for task detect_fraud (Bash command failed. The command returned a non-zero exit code 1.; 509)
[2025-03-20T22:01:14.095+0000] {local_task_job_runner.py:228} INFO - Task exited with return code 1
[2025-03-20T22:01:14.116+0000] {taskinstance.py:2776} INFO - 0 downstream tasks scheduled from follow-on schedule check
