[2025-03-21T13:42:13.770+0000] {taskinstance.py:1157} INFO - Dependencies all met for dep_context=non-requeueable deps ti=<TaskInstance: transactions_pipeline.create_fraud_table_batch_20250321_131625 scheduled__2025-03-21T13:32:39.231672+00:00 [queued]>
[2025-03-21T13:42:13.839+0000] {taskinstance.py:1157} INFO - Dependencies all met for dep_context=requeueable deps ti=<TaskInstance: transactions_pipeline.create_fraud_table_batch_20250321_131625 scheduled__2025-03-21T13:32:39.231672+00:00 [queued]>
[2025-03-21T13:42:13.842+0000] {taskinstance.py:1359} INFO - Starting attempt 1 of 1
[2025-03-21T13:42:14.066+0000] {taskinstance.py:1380} INFO - Executing <Task(BashOperator): create_fraud_table_batch_20250321_131625> on 2025-03-21 13:32:39.231672+00:00
[2025-03-21T13:42:14.122+0000] {standard_task_runner.py:57} INFO - Started process 3661 to run task
[2025-03-21T13:42:14.137+0000] {standard_task_runner.py:84} INFO - Running: ['***', 'tasks', 'run', 'transactions_pipeline', 'create_fraud_table_batch_20250321_131625', 'scheduled__2025-03-21T13:32:39.231672+00:00', '--job-id', '677', '--raw', '--subdir', 'DAGS_FOLDER/fraud_detection_pipeline.py', '--cfg-path', '/tmp/tmp_15jwpoe']
[2025-03-21T13:42:14.175+0000] {standard_task_runner.py:85} INFO - Job 677: Subtask create_fraud_table_batch_20250321_131625
[2025-03-21T13:42:14.795+0000] {task_command.py:415} INFO - Running <TaskInstance: transactions_pipeline.create_fraud_table_batch_20250321_131625 scheduled__2025-03-21T13:32:39.231672+00:00 [running]> on host 1b7c3466167a
[2025-03-21T13:42:15.304+0000] {taskinstance.py:1660} INFO - Exporting env vars: AIRFLOW_CTX_DAG_EMAIL='rabiizahnoune7@gmail.com' AIRFLOW_CTX_DAG_OWNER='***' AIRFLOW_CTX_DAG_ID='transactions_pipeline' AIRFLOW_CTX_TASK_ID='create_fraud_table_batch_20250321_131625' AIRFLOW_CTX_EXECUTION_DATE='2025-03-21T13:32:39.231672+00:00' AIRFLOW_CTX_TRY_NUMBER='1' AIRFLOW_CTX_DAG_RUN_ID='scheduled__2025-03-21T13:32:39.231672+00:00'
[2025-03-21T13:42:15.341+0000] {subprocess.py:63} INFO - Tmp dir root location: /tmp
[2025-03-21T13:42:15.355+0000] {subprocess.py:75} INFO - Running command: ['/bin/bash', '-c', '\n            docker exec hive beeline -u "jdbc:hive2://localhost:10000" -e "\n            CREATE EXTERNAL TABLE IF NOT EXISTS fraud_detections (\n                transaction_id STRING,\n                date_time STRING,\n                amount DOUBLE,\n                customer_id STRING,\n                location STRING,\n                fraud_reason STRING\n            )\n            STORED AS PARQUET\n            LOCATION \'/data/fraud_detections\';"\n            ']
[2025-03-21T13:42:14.192+0000] {subprocess.py:86} INFO - Output:
[2025-03-21T13:42:33.785+0000] {subprocess.py:93} INFO - SLF4J: Class path contains multiple SLF4J bindings.
[2025-03-21T13:42:33.786+0000] {subprocess.py:93} INFO - SLF4J: Found binding in [jar:file:/opt/hive/lib/log4j-slf4j-impl-2.17.1.jar!/org/slf4j/impl/StaticLoggerBinder.class]
[2025-03-21T13:42:33.787+0000] {subprocess.py:93} INFO - SLF4J: Found binding in [jar:file:/opt/hadoop/share/hadoop/common/lib/slf4j-log4j12-1.7.25.jar!/org/slf4j/impl/StaticLoggerBinder.class]
[2025-03-21T13:42:33.787+0000] {subprocess.py:93} INFO - SLF4J: See http://www.slf4j.org/codes.html#multiple_bindings for an explanation.
[2025-03-21T13:42:37.371+0000] {subprocess.py:93} INFO - SLF4J: Actual binding is of type [org.apache.logging.slf4j.Log4jLoggerFactory]
[2025-03-21T13:42:56.814+0000] {subprocess.py:93} INFO - Connecting to jdbc:hive2://localhost:10000
[2025-03-21T13:43:17.148+0000] {job.py:219} ERROR - Job heartbeat got an exception
Traceback (most recent call last):
  File "/home/airflow/.local/lib/python3.8/site-packages/sqlalchemy/engine/base.py", line 3371, in _wrap_pool_connect
    return fn()
  File "/home/airflow/.local/lib/python3.8/site-packages/sqlalchemy/pool/base.py", line 327, in connect
    return _ConnectionFairy._checkout(self)
  File "/home/airflow/.local/lib/python3.8/site-packages/sqlalchemy/pool/base.py", line 894, in _checkout
    fairy = _ConnectionRecord.checkout(pool)
  File "/home/airflow/.local/lib/python3.8/site-packages/sqlalchemy/pool/base.py", line 493, in checkout
    rec = pool._do_get()
  File "/home/airflow/.local/lib/python3.8/site-packages/sqlalchemy/pool/impl.py", line 256, in _do_get
    return self._create_connection()
  File "/home/airflow/.local/lib/python3.8/site-packages/sqlalchemy/pool/base.py", line 273, in _create_connection
    return _ConnectionRecord(self)
  File "/home/airflow/.local/lib/python3.8/site-packages/sqlalchemy/pool/base.py", line 388, in __init__
    self.__connect()
  File "/home/airflow/.local/lib/python3.8/site-packages/sqlalchemy/pool/base.py", line 691, in __connect
    pool.logger.debug("Error on connect(): %s", e)
  File "/home/airflow/.local/lib/python3.8/site-packages/sqlalchemy/util/langhelpers.py", line 70, in __exit__
    compat.raise_(
  File "/home/airflow/.local/lib/python3.8/site-packages/sqlalchemy/util/compat.py", line 211, in raise_
    raise exception
  File "/home/airflow/.local/lib/python3.8/site-packages/sqlalchemy/pool/base.py", line 686, in __connect
    self.dbapi_connection = connection = pool._invoke_creator(self)
  File "/home/airflow/.local/lib/python3.8/site-packages/sqlalchemy/engine/create.py", line 574, in connect
    return dialect.connect(*cargs, **cparams)
  File "/home/airflow/.local/lib/python3.8/site-packages/sqlalchemy/engine/default.py", line 598, in connect
    return self.dbapi.connect(*cargs, **cparams)
  File "/home/airflow/.local/lib/python3.8/site-packages/psycopg2/__init__.py", line 122, in connect
    conn = _connect(dsn, connection_factory=connection_factory, **kwasync)
psycopg2.OperationalError: could not translate host name "postgres" to address: Temporary failure in name resolution


The above exception was the direct cause of the following exception:

Traceback (most recent call last):
  File "/home/airflow/.local/lib/python3.8/site-packages/airflow/jobs/job.py", line 190, in heartbeat
    session.merge(self)
  File "/home/airflow/.local/lib/python3.8/site-packages/sqlalchemy/orm/session.py", line 3056, in merge
    return self._merge(
  File "/home/airflow/.local/lib/python3.8/site-packages/sqlalchemy/orm/session.py", line 3136, in _merge
    merged = self.get(
  File "/home/airflow/.local/lib/python3.8/site-packages/sqlalchemy/orm/session.py", line 2853, in get
    return self._get_impl(
  File "/home/airflow/.local/lib/python3.8/site-packages/sqlalchemy/orm/session.py", line 2975, in _get_impl
    return db_load_fn(
  File "/home/airflow/.local/lib/python3.8/site-packages/sqlalchemy/orm/loading.py", line 530, in load_on_pk_identity
    session.execute(
  File "/home/airflow/.local/lib/python3.8/site-packages/sqlalchemy/orm/session.py", line 1716, in execute
    conn = self._connection_for_bind(bind)
  File "/home/airflow/.local/lib/python3.8/site-packages/sqlalchemy/orm/session.py", line 1555, in _connection_for_bind
    return self._transaction._connection_for_bind(
  File "/home/airflow/.local/lib/python3.8/site-packages/sqlalchemy/orm/session.py", line 750, in _connection_for_bind
    conn = bind.connect()
  File "/home/airflow/.local/lib/python3.8/site-packages/sqlalchemy/future/engine.py", line 406, in connect
    return super(Engine, self).connect()
  File "/home/airflow/.local/lib/python3.8/site-packages/sqlalchemy/engine/base.py", line 3325, in connect
    return self._connection_cls(self, close_with_result=close_with_result)
  File "/home/airflow/.local/lib/python3.8/site-packages/sqlalchemy/engine/base.py", line 96, in __init__
    else engine.raw_connection()
  File "/home/airflow/.local/lib/python3.8/site-packages/sqlalchemy/engine/base.py", line 3404, in raw_connection
    return self._wrap_pool_connect(self.pool.connect, _connection)
  File "/home/airflow/.local/lib/python3.8/site-packages/sqlalchemy/engine/base.py", line 3374, in _wrap_pool_connect
    Connection._handle_dbapi_exception_noconnection(
  File "/home/airflow/.local/lib/python3.8/site-packages/sqlalchemy/engine/base.py", line 2208, in _handle_dbapi_exception_noconnection
    util.raise_(
  File "/home/airflow/.local/lib/python3.8/site-packages/sqlalchemy/util/compat.py", line 211, in raise_
    raise exception
  File "/home/airflow/.local/lib/python3.8/site-packages/sqlalchemy/engine/base.py", line 3371, in _wrap_pool_connect
    return fn()
  File "/home/airflow/.local/lib/python3.8/site-packages/sqlalchemy/pool/base.py", line 327, in connect
    return _ConnectionFairy._checkout(self)
  File "/home/airflow/.local/lib/python3.8/site-packages/sqlalchemy/pool/base.py", line 894, in _checkout
    fairy = _ConnectionRecord.checkout(pool)
  File "/home/airflow/.local/lib/python3.8/site-packages/sqlalchemy/pool/base.py", line 493, in checkout
    rec = pool._do_get()
  File "/home/airflow/.local/lib/python3.8/site-packages/sqlalchemy/pool/impl.py", line 256, in _do_get
    return self._create_connection()
  File "/home/airflow/.local/lib/python3.8/site-packages/sqlalchemy/pool/base.py", line 273, in _create_connection
    return _ConnectionRecord(self)
  File "/home/airflow/.local/lib/python3.8/site-packages/sqlalchemy/pool/base.py", line 388, in __init__
    self.__connect()
  File "/home/airflow/.local/lib/python3.8/site-packages/sqlalchemy/pool/base.py", line 691, in __connect
    pool.logger.debug("Error on connect(): %s", e)
  File "/home/airflow/.local/lib/python3.8/site-packages/sqlalchemy/util/langhelpers.py", line 70, in __exit__
    compat.raise_(
  File "/home/airflow/.local/lib/python3.8/site-packages/sqlalchemy/util/compat.py", line 211, in raise_
    raise exception
  File "/home/airflow/.local/lib/python3.8/site-packages/sqlalchemy/pool/base.py", line 686, in __connect
    self.dbapi_connection = connection = pool._invoke_creator(self)
  File "/home/airflow/.local/lib/python3.8/site-packages/sqlalchemy/engine/create.py", line 574, in connect
    return dialect.connect(*cargs, **cparams)
  File "/home/airflow/.local/lib/python3.8/site-packages/sqlalchemy/engine/default.py", line 598, in connect
    return self.dbapi.connect(*cargs, **cparams)
  File "/home/airflow/.local/lib/python3.8/site-packages/psycopg2/__init__.py", line 122, in connect
    conn = _connect(dsn, connection_factory=connection_factory, **kwasync)
sqlalchemy.exc.OperationalError: (psycopg2.OperationalError) could not translate host name "postgres" to address: Temporary failure in name resolution

(Background on this error at: https://sqlalche.me/e/14/e3q8)
[2025-03-21T13:43:26.327+0000] {subprocess.py:93} INFO - Connected to: Apache Hive (version 3.1.3)
[2025-03-21T13:43:26.328+0000] {subprocess.py:93} INFO - Driver: Hive JDBC (version 3.1.3)
[2025-03-21T13:43:26.329+0000] {subprocess.py:93} INFO - Transaction isolation: TRANSACTION_REPEATABLE_READ
[2025-03-21T13:43:27.204+0000] {subprocess.py:93} INFO - No rows affected (16.679 seconds)
[2025-03-21T13:43:27.530+0000] {subprocess.py:93} INFO - INFO  : Compiling command(queryId=root_20250321134312_32ac73b9-fccc-4011-a18b-94d42b5260ca): CREATE EXTERNAL TABLE IF NOT EXISTS fraud_detections (
[2025-03-21T13:43:27.532+0000] {subprocess.py:93} INFO -                 transaction_id STRING,
[2025-03-21T13:43:27.533+0000] {subprocess.py:93} INFO -                 date_time STRING,
[2025-03-21T13:43:27.534+0000] {subprocess.py:93} INFO -                 amount DOUBLE,
[2025-03-21T13:43:27.535+0000] {subprocess.py:93} INFO -                 customer_id STRING,
[2025-03-21T13:43:27.536+0000] {subprocess.py:93} INFO -                 location STRING,
[2025-03-21T13:43:27.537+0000] {subprocess.py:93} INFO -                 fraud_reason STRING
[2025-03-21T13:43:27.538+0000] {subprocess.py:93} INFO -             )
[2025-03-21T13:43:27.538+0000] {subprocess.py:93} INFO -             STORED AS PARQUET
[2025-03-21T13:43:27.539+0000] {subprocess.py:93} INFO -             LOCATION '/data/fraud_detections'
[2025-03-21T13:43:27.545+0000] {subprocess.py:93} INFO - INFO  : Concurrency mode is disabled, not creating a lock manager
[2025-03-21T13:43:27.547+0000] {subprocess.py:93} INFO - INFO  : Semantic Analysis Completed (retrial = false)
[2025-03-21T13:43:27.548+0000] {subprocess.py:93} INFO - INFO  : Returning Hive schema: Schema(fieldSchemas:null, properties:null)
[2025-03-21T13:43:27.549+0000] {subprocess.py:93} INFO - INFO  : Completed compiling command(queryId=root_20250321134312_32ac73b9-fccc-4011-a18b-94d42b5260ca); Time taken: 0.687 seconds
[2025-03-21T13:43:27.550+0000] {subprocess.py:93} INFO - INFO  : Concurrency mode is disabled, not creating a lock manager
[2025-03-21T13:43:27.551+0000] {subprocess.py:93} INFO - INFO  : Executing command(queryId=root_20250321134312_32ac73b9-fccc-4011-a18b-94d42b5260ca): CREATE EXTERNAL TABLE IF NOT EXISTS fraud_detections (
[2025-03-21T13:43:27.552+0000] {subprocess.py:93} INFO -                 transaction_id STRING,
[2025-03-21T13:43:27.552+0000] {subprocess.py:93} INFO -                 date_time STRING,
[2025-03-21T13:43:27.553+0000] {subprocess.py:93} INFO -                 amount DOUBLE,
[2025-03-21T13:43:27.554+0000] {subprocess.py:93} INFO -                 customer_id STRING,
[2025-03-21T13:43:27.554+0000] {subprocess.py:93} INFO -                 location STRING,
[2025-03-21T13:43:27.555+0000] {subprocess.py:93} INFO -                 fraud_reason STRING
[2025-03-21T13:43:27.556+0000] {subprocess.py:93} INFO -             )
[2025-03-21T13:43:27.557+0000] {subprocess.py:93} INFO -             STORED AS PARQUET
[2025-03-21T13:43:27.558+0000] {subprocess.py:93} INFO -             LOCATION '/data/fraud_detections'
[2025-03-21T13:43:27.559+0000] {subprocess.py:93} INFO - INFO  : Completed executing command(queryId=root_20250321134312_32ac73b9-fccc-4011-a18b-94d42b5260ca); Time taken: 0.297 seconds
[2025-03-21T13:43:27.561+0000] {subprocess.py:93} INFO - INFO  : OK
[2025-03-21T13:43:27.563+0000] {subprocess.py:93} INFO - INFO  : Concurrency mode is disabled, not creating a lock manager
[2025-03-21T13:43:27.633+0000] {subprocess.py:93} INFO - Beeline version 3.1.3 by Apache Hive
[2025-03-21T13:43:27.911+0000] {subprocess.py:93} INFO - Closing: 0: jdbc:hive2://localhost:10000
[2025-03-21T13:43:28.907+0000] {subprocess.py:97} INFO - Command exited with return code 0
[2025-03-21T13:43:28.970+0000] {taskinstance.py:1398} INFO - Marking task as SUCCESS. dag_id=transactions_pipeline, task_id=create_fraud_table_batch_20250321_131625, execution_date=20250321T133239, start_date=20250321T134213, end_date=20250321T134328
[2025-03-21T13:43:29.076+0000] {local_task_job_runner.py:228} INFO - Task exited with return code 0
[2025-03-21T13:43:29.174+0000] {taskinstance.py:2776} INFO - 1 downstream tasks scheduled from follow-on schedule check
